Workbook

Sheet Cover
A1: SMPL · MD&A variance commentary
A2: Aug 2026 close · US01 · GAAP_PRIMARY · USD thousands
A4: Package
A5: Package ID | B5: MDA-US01-2026-08-001
A6: Status | B6: Approved · J. Patel, Controller · 2026-09-10
A7: Data snapshot | B7: SNAP-US01-2026-08-003
A8: Content hash | B8: c33b460e9ec15c44
A9: Generated | B9: 2026-10-07 10:30 PT · SMPL MD&A export v1
A10: Tie-outs | B10: ='Tie-outs'!B28 -> ✓ All pass
A11: If a comparison is reopened | B11: SMPL marks this package Replaced and issues a new package ID. Check the ID in SMPL before distributing.
A12: Data | B12: Synthetic fixture for the SMPL specification; not company data.
A14: Comparisons and sign-off
A15: Tab | B15: Comparison | C15: Status | D15: Approved by | E15: Approved | F15: Lines in scope | G15: Reviewed | H15: Tie-outs
A16: MoM | B16: Aug 2026 vs Jul 2026 | C16: Approved | D16: J. Patel, Controller | E16: 2026-09-10 | F16: 87 | G16: 87 | H16: =IF(COUNTIF('Tie-outs'!B6:B40,"✗")=0,"✓","✗") -> ✓
A17: QoQ | B17: Q3 2026 QTD vs prior quarter (same months) | C17: Approved | D17: J. Patel, Controller | E17: 2026-09-10 | F17: 97 | G17: 97 | H17: =IF(COUNTIF('Tie-outs'!C6:C40,"✗")=0,"✓","✗") -> ✓
A18: YoY | B18: Aug 2026 vs Aug 2025 | C18: Approved | D18: J. Patel, Controller | E18: 2026-09-10 | F18: 134 | G18: 134 | H18: =IF(COUNTIF('Tie-outs'!D6:D40,"✗")=0,"✓","✗") -> ✓
A19: YTD | B19: YTD 2026 vs YTD 2025 (Jan–Aug) | C19: Approved | D19: J. Patel, Controller | E19: 2026-09-10 | F19: 148 | G19: 148 | H19: =IF(COUNTIF('Tie-outs'!E6:E40,"✗")=0,"✓","✗") -> ✓
A20: Budget M | B20: Aug 2026 vs Budget 2026 v1 | C20: Approved | D20: J. Patel, Controller | E20: 2026-09-10 | F20: 57 | G20: 57 | H20: =IF(COUNTIF('Tie-outs'!F6:F40,"✗")=0,"✓","✗") -> ✓
A21: Budget YTD | B21: YTD Aug 2026 vs Budget 2026 v1 | C21: Approved | D21: J. Patel, Controller | E21: 2026-09-10 | F21: 76 | G21: 76 | H21: =IF(COUNTIF('Tie-outs'!G6:G40,"✗")=0,"✓","✗") -> ✓
A22: Forecast M | B22: Aug 2026 vs Forecast 2026 7+5 | C22: Approved | D22: J. Patel, Controller | E22: 2026-09-10 | F22: 40 | G22: 40 | H22: =IF(COUNTIF('Tie-outs'!H6:H40,"✗")=0,"✓","✗") -> ✓
A24: Contents
A25: Executive summary | B25: AI-written summary for each comparison, key lines, and the check that cited components add up to the net income change
A26: NI walk | B26: Comparison net income to August net income by statement subtotal, for the accounting and management views
A27: Comparison matrix | B27: Variance of every statement line across all seven comparisons
A28: MoM | B28: Aug 2026 vs Jul 2026: income statement, management P&L, GL detail, balance sheet and cash flow, with approved commentary
A29: QoQ | B29: Q3 2026 QTD vs prior quarter (same months): income statement, management P&L, GL detail, balance sheet and cash flow, with approved commentary
A30: YoY | B30: Aug 2026 vs Aug 2025: income statement, management P&L, GL detail, balance sheet and cash flow, with approved commentary
A31: YTD | B31: YTD 2026 vs YTD 2025 (Jan–Aug): income statement, management P&L, GL detail, balance sheet and cash flow, with approved commentary
A32: Budget M | B32: Aug 2026 vs Budget 2026 v1: income statement, management P&L, GL detail, balance sheet and cash flow, with approved commentary
A33: Budget YTD | B33: YTD Aug 2026 vs Budget 2026 v1: income statement, management P&L, GL detail, balance sheet and cash flow, with approved commentary
A34: Forecast M | B34: Aug 2026 vs Forecast 2026 7+5: income statement, management P&L, GL detail, balance sheet and cash flow, with approved commentary
A35: Labor bridge | B35: Compensation bridge month over month and vs budget, company and by department (§18)
A36: Watch list | B36: Future impacts by month with the net income effect, and how last month's watch list played out
... A39: Commentary drivers | B39: The drivers and component lines each paragraph cites
A41: How to read this workbook
A42: Blue numbers | B42: Ledger amounts from the data snapshot (and the labor engine's bars).
A43: Black numbers | B43: Formulas: roll-ups, variances, percentages, walks, checks.
A44: Green numbers | B44: Links to another sheet in this workbook.
A45: ✓ / ✗ | B45: A tie-out that passes or fails. Every ✓ is a live formula except SMPL's export validations.
A46: F / U | B46: Favorable or unfavorable for the line (revenue up or cost down is favorable).
...

Sheet Executive summary
A1: Executive summary · August 2026
A2: Package MDA-US01-2026-08-001 · US01 · GAAP_PRIMARY · USD thousands · Snapshot SNAP-US01-2026-08-003 · Content hash c33b460e9ec15c44
A3: Drafted by AI from approved lines only. Every amount is bound to a line in this package, and the net income components it cites add up to the net income change (checked below each summary).
A5: MoM · Aug 2026 vs Jul 2026 | F5: Approved · J. Patel, Controller · 2026-09-10
A6: Net income fell 39.2k (19.7%) vs Jul 2026. Higher cost of revenue (−26.5k) and higher operating expenses (−15.2k) outweighed higher net revenue (+8.5k); other lines contributed −6.0k. Revenue growth was mostly a change in mix: new logos (+55.6k; ENT-12, MM-18) and the P-107 ENT-12 implementation (+45.0k) replaced the completed P-105 ENT-03 rollout (−60.0k). Cost of revenue rose on pay rate changes (+5.8k) and production hosting (+4.0k). Within operating expenses, research and development (+21.6k) and general and administrative (+9.4k) rose, while sales and marketing fell (−15.8k) because the July customer conference (−55.0k) did not recur.
A7: AI draft · validated: no number outside a bound token; net income components cited once each.
A9: Key lines | B9: Aug 2026 | C9: Jul 2026 | D9: Variance | E9: % | F9: F/U
A10: Total net revenue | B10: =MoM!B10 -> 2000 | C10: =MoM!C10 -> 1991.527 | D10: =B10-C10 -> 8.473 | E10: =IF(C10=0,"n/m",D10/ABS(C10)) -> 0.0042545243 | F10: =MoM!F10 -> F
A11: Gross profit | B11: =MoM!B21 -> 1340 | C11: =MoM!C21 -> 1358.0278 | D11: =B11-C11 -> -18.02782 | E11: =IF(C11=0,"n/m",D11/ABS(C11)) -> -0.013275001 | F11: =MoM!F21 -> U
A12: Gross margin % | B12: =IF(B10=0,0,B11/B10) -> 0.67 | C12: =IF(C10=0,0,C11/C10) -> 0.68190279 | D12: =B12-C12 -> -0.011902791 | E12: pts
A13: Total operating expenses | B13: =MoM!B42 -> 1120 | C13: =MoM!C42 -> 1104.8268 | D13: =B13-C13 -> 15.17318 | E13: =IF(C13=0,"n/m",D13/ABS(C13)) -> 0.013733537 | F13: =MoM!F42 -> U
A14: Operating income | B14: =MoM!B43 -> 220 | C14: =MoM!C43 -> 253.201 | D14: =B14-C14 -> -33.201 | E14: =IF(C14=0,"n/m",D14/ABS(C14)) -> -0.13112507 | F14: =MoM!F43 -> U
A15: Net income | B15: =MoM!B48 -> 160 | C15: =MoM!C48 -> 199.201 | D15: =B15-C15 -> -39.201 | E15: =IF(C15=0,"n/m",D15/ABS(C15)) -> -0.19679118 | F15: =MoM!F48 -> U
A16: Contribution after direct go-to-market (management view) | B16: =MoM!B72 -> 900 | C16: =MoM!C72 -> 901.94092 | D16: =B16-C16 -> -1.94092 | E16: =IF(C16=0,"n/m",D16/ABS(C16)) -> -0.002151937 | F16: =MoM!F72 -> U
A18: Net income components cited in the summary | B18: Shown
A19: Total cost of revenue | B19: -26.5
A20: Total operating expenses | B20: -15.2
A21: Total net revenue | B21: 8.5
A22: Other (2 items) | B22: -6
A23: Sum of cited components | B23: =SUM(B19:B22) -> -39.2 | C23: Net income change | D23: =ROUND(D15,1) -> -39.2 | E23: =IF(ROUND(B23-D23,1)=0,"✓","✗") -> ✓
A26: QoQ · Q3 2026 QTD vs prior quarter (same months) | F26: Approved · J. Patel, Controller · 2026-09-10
A27: Net income fell 48.5k (11.9%) in Jul–Aug against the same months of the prior quarter. Higher net revenue (+267.2k) was more than offset by higher operating expenses (−247.5k) and cost of revenue (−55.7k), with other lines at −12.5k. Revenue growth came from the P-107 ENT-12 implementation (+125.0k), new logos (+122.3k) and expansion (+68.0k). Sales and marketing (+152.7k) drove the operating expense increase, led by events & conferences (+77.3k) for the annual customer conference held in July; general and administrative (+49.9k) and research and development (+44.9k) also rose.
A28: AI draft · validated: no number outside a bound token; net income components cited once each.
A30: Key lines | B30: Jul–Aug 2026 | C30: Apr–May 2026 | D30: Variance | E30: % | F30: F/U
A31: Total net revenue | B31: =QoQ!B10 -> 3991.527 | C31: =QoQ!C10 -> 3724.337 | D31: =B31-C31 -> 267.19 | E31: =IF(C31=0,"n/m",D31/ABS(C31)) -> 0.071741628 | F31: =QoQ!F10 -> F
A32: Gross profit | B32: =QoQ!B21 -> 2698.0278 | C32: =QoQ!C21 -> 2486.4983 | D32: =B32-C32 -> 211.52955 | E32: =IF(C32=0,"n/m",D32/ABS(C32)) -> 0.085071264 | F32: =QoQ!F21 -> F
A33: Gross margin % | B33: =IF(B31=0,0,B32/B31) -> 0.67593876 | C33: =IF(C31=0,0,C32/C31) -> 0.66763514 | D33: =B33-C33 -> 0.0083036181 | E33: pts
A34: Total operating expenses | B34: =QoQ!B42 -> 2224.8268 | C34: =QoQ!C42 -> 1977.2933 | D34: =B34-C34 -> 247.53355 | E34: =IF(C34=0,"n/m",D34/ABS(C34)) -> 0.12518808 | F34: =QoQ!F42 -> U
A35: Operating income | B35: =QoQ!B43 -> 473.201 | C35: =QoQ!C43 -> 509.205 | D35: =B35-C35 -> -36.004 | E35: =IF(C35=0,"n/m",D35/ABS(C35)) -> -0.070706297 | F35: =QoQ!F43 -> U
A36: Net income | B36: =QoQ!B48 -> 359.201 | C36: =QoQ!C48 -> 407.705 | D36: =B36-C36 -> -48.504 | E36: =IF(C36=0,"n/m",D36/ABS(C36)) -> -0.11896837 | F36: =QoQ!F48 -> U
A37: Contribution after direct go-to-market (management view) | B37: =QoQ!B72 -> 1801.9409 | C37: =QoQ!C72 -> 1739.6287 | D37: =B37-C37 -> 62.31225 | E37: =IF(C37=0,"n/m",D37/ABS(C37)) -> 0.035819282 | F37: =QoQ!F72 -> F
A39: Net income components cited in the summary | B39: Shown
A40: Total net revenue | B40: 267.2
A41: Total operating expenses | B41: -247.5
A42: Total cost of revenue | B42: -55.7
A43: Other (3 items) | B43: -12.5
A44: Sum of cited components | B44: =SUM(B40:B43) -> -48.5 | C44: Net income change | D44: =ROUND(D36,1) -> -48.5 | E44: =IF(ROUND(B44-D44,1)=0,"✓","✗") -> ✓
A47: YoY · Aug 2026 vs Aug 2025 | F47: Approved · J. Patel, Controller · 2026-09-10
A48: Net income fell 86.0k (35.0%) vs Aug 2025. Higher net revenue (+376.4k) was more than offset by higher operating expenses (−300.4k) and cost of revenue (−145.0k); other lines were −17.0k. New logos (+381.8k) drove revenue, net of churned customers (−145.8k). Operating expenses rose in sales and marketing (+147.5k), research and development (+100.0k) and general and administrative (+52.9k), with compensation up 243.8k, mostly base pay (+191.8k).
A49: AI draft · validated: no number outside a bound token; net income components cited once each.
...

Sheet NI walk
A1: Net income walk · comparison net income to August 2026
A2: Package MDA-US01-2026-08-001 · US01 · GAAP_PRIMARY · USD thousands · Snapshot SNAP-US01-2026-08-003 · Content hash c33b460e9ec15c44
A3: Each step is a statement subtotal's variance times its sign in net income (the same component lines the net income commentary cites). Steps link to the comparison tabs; the walk must land on the statement's net income.
A5: Income statement walk
A6: USD thousands | B6: MoM | C6: QoQ | D6: YoY | E6: YTD | F6: vs Budget (month) | G6: vs Budget (YTD) | H6: vs Forecast 7+5 (month)
A7: Comparison net income | B7: =MoM!C48 -> 199.201 | C7: =QoQ!C48 -> 407.705 | D7: =YoY!C48 -> 245.985 | E7: =YTD!C48 -> 1645.693 | F7: ='Budget M'!C48 -> 108.079 | G7: ='Budget YTD'!C48 -> 1540.969 | H7: ='Forecast M'!C48 -> 171.224
A8: + Total net revenue | B8: =MoM!D10 -> 8.473 | C8: =QoQ!D10 -> 267.19 | D8: =YoY!D10 -> 376.381 | E8: =YTD!D10 -> 3135.667 | F8: ='Budget M'!D10 -> -30 | G8: ='Budget YTD'!D10 -> -466.603 | H8: ='Forecast M'!D10 -> 0.238
A9: − Total cost of revenue | B9: =-MoM!D20 -> -26.50082 | C9: =-QoQ!D20 -> -55.66045 | D9: =-YoY!D20 -> -144.93782 | E9: =-YTD!D20 -> -1099.4957 | F9: =-'Budget M'!D20 -> 7.77377 | G9: =-'Budget YTD'!D20 -> 90.0032 | H9: =-'Forecast M'!D20 -> -7.20485
A10: − Total operating expenses | B10: =-MoM!D42 -> -15.17318 | C10: =-QoQ!D42 -> -247.53355 | D10: =-YoY!D42 -> -300.42818 | E10: =-YTD!D42 -> -1904.9393 | F10: =-'Budget M'!D42 -> 67.14723 | G10: =-'Budget YTD'!D42 -> 472.5558 | H10: =-'Forecast M'!D42 -> -2.25715
A11: + Interest income | B11: =MoM!D44 -> -1 | C11: =QoQ!D44 -> -1.5 | D11: =YoY!D44 -> -3 | E11: =YTD!D44 -> -18.5 | F11: ='Budget M'!D44 -> 2 | G11: ='Budget YTD'!D44 -> 17.5 | H11: ='Forecast M'!D44 -> 0
A12: − Interest expense | B12: =-MoM!D45 -> 0 | C12: =-QoQ!D45 -> 0.5 | D12: =-YoY!D45 -> 2 | E12: =-YTD!D45 -> 17.5 | F12: =-'Budget M'!D45 -> 0 | G12: =-'Budget YTD'!D45 -> 1.5 | H12: =-'Forecast M'!D45 -> 0
A13: − Income tax | B13: =-MoM!D47 -> -5 | C13: =-QoQ!D47 -> -11.5 | D13: =-YoY!D47 -> -16 | E13: =-YTD!D47 -> -80.5 | F13: =-'Budget M'!D47 -> 5 | G13: =-'Budget YTD'!D47 -> 39.5 | H13: =-'Forecast M'!D47 -> -2
A14: Current net income (walk) | B14: =B7+SUM(B8:B13) -> 160 | C14: =C7+SUM(C8:C13) -> 359.201 | D14: =D7+SUM(D8:D13) -> 160 | E14: =E7+SUM(E8:E13) -> 1695.425 | F14: =F7+SUM(F8:F13) -> 160 | G14: =G7+SUM(G8:G13) -> 1695.425 | H14: =H7+SUM(H8:H13) -> 160
A15: Current net income (statement) | B15: =MoM!B48 -> 160 | C15: =QoQ!B48 -> 359.201 | D15: =YoY!B48 -> 160 | E15: =YTD!B48 -> 1695.425 | F15: ='Budget M'!B48 -> 160 | G15: ='Budget YTD'!B48 -> 1695.425 | H15: ='Forecast M'!B48 -> 160
A16: Walk lands on net income | B16: =IF(ROUND(B14-B15,4)=0,"✓","✗") -> ✓ | C16: =IF(ROUND(C14-C15,4)=0,"✓","✗") -> ✓ | D16: =IF(ROUND(D14-D15,4)=0,"✓","✗") -> ✓ | E16: =IF(ROUND(E14-E15,4)=0,"✓","✗") -> ✓ | F16: =IF(ROUND(F14-F15,4)=0,"✓","✗") -> ✓ | G16: =IF(ROUND(G14-G15,4)=0,"✓","✗") -> ✓ | H16: =IF(ROUND(H14-H15,4)=0,"✓","✗") -> ✓
A18: Management P&L walk (allocations included)
A19: USD thousands | B19: MoM | C19: QoQ | D19: YoY | E19: YTD | F19: vs Budget (month) | G19: vs Budget (YTD) | H19: vs Forecast 7+5 (month)
A20: Comparison net income | B20: =MoM!C92 -> 199.201 | C20: =QoQ!C92 -> 407.705 | D20: =YoY!C92 -> 245.985 | E20: =YTD!C92 -> 1645.693 | F20: ='Budget M'!C92 -> 108.079 | G20: ='Budget YTD'!C92 -> 1540.969 | H20: ='Forecast M'!C92 -> 171.224
A21: + Total net revenue | B21: =MoM!D53 -> 8.473 | C21: =QoQ!D53 -> 267.19 | D21: =YoY!D53 -> 376.381 | E21: =YTD!D53 -> 3135.667 | F21: ='Budget M'!D53 -> -30 | G21: ='Budget YTD'!D53 -> -466.603 | H21: ='Forecast M'!D53 -> 0.238
A22: − Service delivery cost | B22: =-MoM!D64 -> -26.70082 | C22: =-QoQ!D64 -> -56.22045 | D22: =-YoY!D64 -> -145.98782 | E22: =-YTD!D64 -> -1105.4797 | F22: =-'Budget M'!D64 -> 7.87377 | G22: =-'Budget YTD'!D64 -> 92.4032 | H22: =-'Forecast M'!D64 -> -7.20485
A23: − S&M — direct go-to-market | B23: =-MoM!D66 -> 16.2869 | C23: =-QoQ!D66 -> -148.6573 | D23: =-YoY!D66 -> -138.0231 | E23: =-YTD!D66 -> -865.0437 | F23: =-'Budget M'!D66 -> 31.9539 | G23: =-'Budget YTD'!D66 -> 184.1209 | H23: =-'Forecast M'!D66 -> 6.1891
A24: − Shared S&M, R&D and G&A (with allocations) | B24: =-MoM!D87 -> -31.26008 | C24: =-QoQ!D87 -> -98.31625 | D24: =-YoY!D87 -> -161.35508 | E24: =-YTD!D87 -> -1033.9116 | F24: =-'Budget M'!D87 -> 35.09333 | G24: =-'Budget YTD'!D87 -> 286.0349 | H24: =-'Forecast M'!D87 -> -8.44625
A25: + Interest income | B25: =MoM!D89 -> -1 | C25: =QoQ!D89 -> -1.5 | D25: =YoY!D89 -> -3 | E25: =YTD!D89 -> -18.5 | F25: ='Budget M'!D89 -> 2 | G25: ='Budget YTD'!D89 -> 17.5 | H25: ='Forecast M'!D89 -> 0
A26: − Interest expense | B26: =-MoM!D90 -> 0 | C26: =-QoQ!D90 -> 0.5 | D26: =-YoY!D90 -> 2 | E26: =-YTD!D90 -> 17.5 | F26: =-'Budget M'!D90 -> 0 | G26: =-'Budget YTD'!D90 -> 1.5 | H26: =-'Forecast M'!D90 -> 0
A27: − Income tax | B27: =-MoM!D91 -> -5 | C27: =-QoQ!D91 -> -11.5 | D27: =-YoY!D91 -> -16 | E27: =-YTD!D91 -> -80.5 | F27: =-'Budget M'!D91 -> 5 | G27: =-'Budget YTD'!D91 -> 39.5 | H27: =-'Forecast M'!D91 -> -2
A28: Current net income (walk) | B28: =B20+SUM(B21:B27) -> 160 | C28: =C20+SUM(C21:C27) -> 359.201 | D28: =D20+SUM(D21:D27) -> 160 | E28: =E20+SUM(E21:E27) -> 1695.425 | F28: =F20+SUM(F21:F27) -> 160 | G28: =G20+SUM(G21:G27) -> 1695.425 | H28: =H20+SUM(H21:H27) -> 160
A29: Current net income (statement) | B29: =MoM!B92 -> 160 | C29: =QoQ!B92 -> 359.201 | D29: =YoY!B92 -> 160 | E29: =YTD!B92 -> 1695.425 | F29: ='Budget M'!B92 -> 160 | G29: ='Budget YTD'!B92 -> 1695.425 | H29: ='Forecast M'!B92 -> 160
A30: Walk lands on net income | B30: =IF(ROUND(B28-B29,4)=0,"✓","✗") -> ✓ | C30: =IF(ROUND(C28-C29,4)=0,"✓","✗") -> ✓ | D30: =IF(ROUND(D28-D29,4)=0,"✓","✗") -> ✓ | E30: =IF(ROUND(E28-E29,4)=0,"✓","✗") -> ✓ | F30: =IF(ROUND(F28-F29,4)=0,"✓","✗") -> ✓ | G30: =IF(ROUND(G28-G29,4)=0,"✓","✗") -> ✓ | H30: =IF(ROUND(H28-H29,4)=0,"✓","✗") -> ✓

Sheet Comparison matrix
A1: Comparison matrix · variance by line across every comparison
A2: Package MDA-US01-2026-08-001 · US01 · GAAP_PRIMARY · USD thousands · Snapshot SNAP-US01-2026-08-003 · Content hash c33b460e9ec15c44
A3: Links to the comparison tabs. Statement lines only; open a tab for GL lines and commentary.
A5: Line (USD thousands) | B5: MoM | D5: QoQ | F5: YoY | H5: YTD | J5: vs Budget (month) | L5: vs Budget (YTD) | N5: vs Forecast 7+5 (month)
B6: Variance | C6: % | D6: Variance | E6: % | F6: Variance | G6: % | H6: Variance | I6: % | J6: Variance | K6: % | L6: Variance | M6: % | N6: Variance | O6: %
A7: INCOME STATEMENT · accounting view
A8: Subscription revenue | B8: =MoM!D8 -> 23.473 | C8: =MoM!E8 -> 0.013212859 | D8: =QoQ!D8 -> 132.19 | E8: =QoQ!E8 -> 0.038378939 | F8: =YoY!D8 -> 306.381 | G8: =YoY!E8 -> 0.20512661 | H8: =YTD!D8 -> 2695.667 | I8: =YTD!E8 -> 0.24233573 | J8: ='Budget M'!D8 -> -50 | K8: ='Budget M'!E8 -> -0.027027027 | L8: ='Budget YTD'!D8 -> -436.603 | M8: ='Budget YTD'!E8 -> -0.030626002 | N8: ='Forecast M'!D8 -> 5.238 | O8: ='Forecast M'!E8 -> 0.0029184928
A9: Professional services revenue | B9: =MoM!D9 -> -15 | C9: =MoM!E9 -> -0.069767442 | D9: =QoQ!D9 -> 135 | E9: =QoQ!E9 -> 0.48214286 | F9: =YoY!D9 -> 70 | G9: =YoY!E9 -> 0.53846154 | H9: =YTD!D9 -> 440 | I9: =YTD!E9 -> 0.49438202 | J9: ='Budget M'!D9 -> 20 | K9: ='Budget M'!E9 -> 0.11111111 | L9: ='Budget YTD'!D9 -> -30 | M9: ='Budget YTD'!E9 -> -0.022058824 | N9: ='Forecast M'!D9 -> -5 | O9: ='Forecast M'!E9 -> -0.024390244
A10: Total net revenue | B10: =MoM!D10 -> 8.473 | C10: =MoM!E10 -> 0.0042545243 | D10: =QoQ!D10 -> 267.19 | E10: =QoQ!E10 -> 0.071741628 | F10: =YoY!D10 -> 376.381 | G10: =YoY!E10 -> 0.23181608 | H10: =YTD!D10 -> 3135.667 | I10: =YTD!E10 -> 0.26100786 | J10: ='Budget M'!D10 -> -30 | K10: ='Budget M'!E10 -> -0.014778325 | L10: ='Budget YTD'!D10 -> -466.603 | M10: ='Budget YTD'!E10 -> -0.029879883 | N10: ='Forecast M'!D10 -> 0.238 | O10: ='Forecast M'!E10 -> 0.00011901416
A11: Cost of revenue — subscription & service delivery | B11: =MoM!D11 -> 25.61282 | C11: =MoM!E11 -> 0.049792882 | D11: =QoQ!D11 -> 55.73645 | E11: =QoQ!E11 -> 0.055811755 | F11: =YoY!D11 -> 128.53282 | G11: =YoY!E11 -> 0.31237685 | H11: =YTD!D11 -> 888.0797 | I11: =YTD!E11 -> 0.28679647 | J11: ='Budget M'!D11 -> -8.36177 | K11: ='Budget M'!E11 -> -0.015248638 | L11: ='Budget YTD'!D11 -> -90.5912 | M11: ='Budget YTD'!E11 -> -0.022229763 | N11: ='Forecast M'!D11 -> 6.61685 | O11: ='Forecast M'!E11 -> 0.012405435
A12: Cost of revenue — professional services | B12: =MoM!D19 -> 0.888 | C12: =MoM!E19 -> 0.0074551682 | D12: =QoQ!D19 -> -0.076 | E12: =QoQ!E19 -> -0.00031774169 | F12: =YoY!D19 -> 16.405 | G12: =YoY!E19 -> 0.15835706 | H12: =YTD!D19 -> 211.416 | I12: =YTD!E19 -> 0.28258429 | J12: ='Budget M'!D19 -> 0.588 | K12: ='Budget M'!E19 -> 0.0049241282 | L12: ='Budget YTD'!D19 -> 0.588 | M12: ='Budget YTD'!E19 -> 0.00061315147 | N12: ='Forecast M'!D19 -> 0.588 | O12: ='Forecast M'!E19 -> 0.0049241282
A13: Total cost of revenue | B13: =MoM!D20 -> 26.50082 | C13: =MoM!E20 -> 0.041832446 | D13: =QoQ!D20 -> 55.66045 | E13: =QoQ!E20 -> 0.044965833 | F13: =YoY!D20 -> 144.93782 | G13: =YoY!E20 -> 0.28139868 | H13: =YTD!D20 -> 1099.4957 | I13: =YTD!E20 -> 0.28597681 | J13: ='Budget M'!D20 -> -7.77377 | K13: ='Budget M'!E20 -> -0.011641323 | L13: ='Budget YTD'!D20 -> -90.0032 | M13: ='Budget YTD'!E20 -> -0.017878348 | N13: ='Forecast M'!D20 -> 7.20485 | O13: ='Forecast M'!E20 -> 0.011036923
A14: Gross profit | B14: =MoM!D21 -> -18.02782 | C14: =MoM!E21 -> -0.013275001 | D14: =QoQ!D21 -> 211.52955 | E14: =QoQ!E21 -> 0.085071264 | F14: =YoY!D21 -> 231.44318 | G14: =YoY!E21 -> 0.20877882 | H14: =YTD!D21 -> 2036.1713 | I14: =YTD!E21 -> 0.24925632 | J14: ='Budget M'!D21 -> -22.22623 | K14: ='Budget M'!E21 -> -0.016316108 | L14: ='Budget YTD'!D21 -> -376.5998 | M14: ='Budget YTD'!E21 -> -0.035589535 | N14: ='Forecast M'!D21 -> -6.96685 | O14: ='Forecast M'!E21 -> -0.0051722505
A15: Research and development | B15: =MoM!D22 -> 21.56342 | C15: =MoM!E22 -> 0.054947528 | D15: =QoQ!D22 -> 44.95027 | E15: =QoQ!E22 -> 0.05902965 | F15: =YoY!D22 -> 99.97342 | G15: =YoY!E22 -> 0.31835974 | H15: =YTD!D22 -> 692.32815 | I15: =YTD!E22 -> 0.29221988 | J15: ='Budget M'!D22 -> -36.65167 | K15: ='Budget M'!E22 -> -0.081330377 | L15: ='Budget YTD'!D22 -> -201.96158 | M15: ='Budget YTD'!E22 -> -0.061885105 | N15: ='Forecast M'!D22 -> -8.95375 | O15: ='Forecast M'!E22 -> -0.021169572
A16: Sales and marketing | B16: =MoM!D28 -> -15.77357 | C16: =MoM!E28 -> -0.031187019 | D16: =QoQ!D28 -> 152.6933 | E16: =QoQ!E28 -> 0.1811136 | F16: =YoY!D28 -> 147.54643 | G16: =YoY!E28 -> 0.4308509 | H16: =YTD!D28 -> 946.50831 | I16: =YTD!E28 -> 0.37112258 | J16: ='Budget M'!D28 -> -34.13723 | K16: ='Budget M'!E28 -> -0.065130329 | L16: ='Budget YTD'!D28 -> -198.82755 | M16: ='Budget YTD'!E28 -> -0.053799284 | N16: ='Forecast M'!D28 -> -7.7891 | O16: ='Forecast M'!E28 -> -0.01564739
A17: General and administrative | B17: =MoM!D37 -> 9.38333 | C17: =MoM!E37 -> 0.045414196 | D17: =QoQ!D37 -> 49.88998 | E17: =QoQ!E37 -> 0.13385138 | F17: =YoY!D37 -> 52.90833 | G17: =YoY!E37 -> 0.32440854 | H17: =YTD!D37 -> 266.10284 | I17: =YTD!E37 -> 0.20925016 | J17: ='Budget M'!D37 -> 3.64167 | K17: ='Budget M'!E37 -> 0.017148703 | L17: ='Budget YTD'!D37 -> -71.76667 | M17: ='Budget YTD'!E37 -> -0.044587572 | N17: ='Forecast M'!D37 -> 19 | O17: ='Forecast M'!E37 -> 0.096446701
A18: Total operating expenses | B18: =MoM!D42 -> 15.17318 | C18: =MoM!E42 -> 0.013733537 | D18: =QoQ!D42 -> 247.53355 | E18: =QoQ!E42 -> 0.12518808 | F18: =YoY!D42 -> 300.42818 | G18: =YoY!E42 -> 0.36656724 | H18: =YTD!D42 -> 1904.9393 | I18: =YTD!E42 -> 0.30768038 | J18: ='Budget M'!D42 -> -67.14723 | K18: ='Budget M'!E42 -> -0.056561839 | L18: ='Budget YTD'!D42 -> -472.5558 | M18: ='Budget YTD'!E42 -> -0.055148501 | N18: ='Forecast M'!D42 -> 2.25715 | O18: ='Forecast M'!E42 -> 0.0020193822
A19: Operating income | B19: =MoM!D43 -> -33.201 | C19: =MoM!E43 -> -0.13112507 | D19: =QoQ!D43 -> -36.004 | E19: =QoQ!E43 -> -0.070706297 | F19: =YoY!D43 -> -68.985 | G19: =YoY!E43 -> -0.23871481 | H19: =YTD!D43 -> 131.232 | I19: =YTD!E43 -> 0.066356103 | J19: ='Budget M'!D43 -> 44.921 | K19: ='Budget M'!E43 -> 0.2565756 | L19: ='Budget YTD'!D43 -> 95.956 | M19: ='Budget YTD'!E43 -> 0.047668891 | N19: ='Forecast M'!D43 -> -9.224 | O19: ='Forecast M'!E43 -> -0.040240114
A20: Interest income | B20: =MoM!D44 -> -1 | C20: =MoM!E44 -> -0.090909091 | D20: =QoQ!D44 -> -1.5 | E20: =QoQ!E44 -> -0.066666667 | F20: =YoY!D44 -> -3 | G20: =YoY!E44 -> -0.23076923 | H20: =YTD!D44 -> -18.5 | I20: =YTD!E44 -> -0.1712963 | J20: ='Budget M'!D44 -> 2 | K20: ='Budget M'!E44 -> 0.25 | L20: ='Budget YTD'!D44 -> 17.5 | M20: ='Budget YTD'!E44 -> 0.24305556 | N20: ='Forecast M'!D44 -> 0 | O20: ='Forecast M'!E44 -> 0
A21: Interest expense | B21: =MoM!D45 -> 0 | C21: =MoM!E45 -> 0 | D21: =QoQ!D45 -> -0.5 | E21: =QoQ!E45 -> -0.0082644628 | F21: =YoY!D45 -> -2 | G21: =YoY!E45 -> -0.0625 | H21: =YTD!D45 -> -17.5 | I21: =YTD!E45 -> -0.067307692 | J21: ='Budget M'!D45 -> 0 | K21: ='Budget M'!E45 -> 0 | L21: ='Budget YTD'!D45 -> -1.5 | M21: ='Budget YTD'!E45 -> -0.006147541 | N21: ='Forecast M'!D45 -> 0 | O21: ='Forecast M'!E45 -> 0
A22: Income before income taxes | B22: =MoM!D46 -> -34.201 | C22: =MoM!E46 -> -0.14603268 | D22: =QoQ!D46 -> -37.004 | E22: =QoQ!E46 -> -0.078530576 | F22: =YoY!D46 -> -69.985 | G22: =YoY!E46 -> -0.2592181 | H22: =YTD!D46 -> 130.232 | I22: =YTD!E46 -> 0.071332913 | J22: ='Budget M'!D46 -> 46.921 | K22: ='Budget M'!E46 -> 0.30651494 | L22: ='Budget YTD'!D46 -> 114.956 | M22: ='Budget YTD'!E46 -> 0.062443202 | N22: ='Forecast M'!D46 -> -9.224 | O22: ='Forecast M'!E46 -> -0.04408672
A23: Income tax expense | B23: =MoM!D47 -> 5 | C23: =MoM!E47 -> 0.14285714 | D23: =QoQ!D47 -> 11.5 | E23: =QoQ!E47 -> 0.18110236 | F23: =YoY!D47 -> 16 | G23: =YoY!E47 -> 0.66666667 | H23: =YTD!D47 -> 80.5 | I23: =YTD!E47 -> 0.44722222 | J23: ='Budget M'!D47 -> -5 | K23: ='Budget M'!E47 -> -0.11111111 | L23: ='Budget YTD'!D47 -> -39.5 | M23: ='Budget YTD'!E47 -> -0.13166667 | N23: ='Forecast M'!D47 -> 2 | O23: ='Forecast M'!E47 -> 0.052631579
A24: Net income | B24: =MoM!D48 -> -39.201 | C24: =MoM!E48 -> -0.19679118 | D24: =QoQ!D48 -> -48.504 | E24: =QoQ!E48 -> -0.11896837 | F24: =YoY!D48 -> -85.985 | G24: =YoY!E48 -> -0.34955383 | H24: =YTD!D48 -> 49.732 | I24: =YTD!E48 -> 0.030219488 | J24: ='Budget M'!D48 -> 51.921 | K24: ='Budget M'!E48 -> 0.4803986 | L24: ='Budget YTD'!D48 -> 154.456 | M24: ='Budget YTD'!E48 -> 0.10023304 | N24: ='Forecast M'!D48 -> -11.224 | O24: ='Forecast M'!E48 -> -0.065551558
A26: MANAGEMENT P&L · functional view with allocations
A27: Subscription revenue | B27: =MoM!D51 -> 23.473 | C27: =MoM!E51 -> 0.013212859 | D27: =QoQ!D51 -> 132.19 | E27: =QoQ!E51 -> 0.038378939 | F27: =YoY!D51 -> 306.381 | G27: =YoY!E51 -> 0.20512661 | H27: =YTD!D51 -> 2695.667 | I27: =YTD!E51 -> 0.24233573 | J27: ='Budget M'!D51 -> -50 | K27: ='Budget M'!E51 -> -0.027027027 | L27: ='Budget YTD'!D51 -> -436.603 | M27: ='Budget YTD'!E51 -> -0.030626002 | N27: ='Forecast M'!D51 -> 5.238 | O27: ='Forecast M'!E51 -> 0.0029184928
A28: Professional services revenue | B28: =MoM!D52 -> -15 | C28: =MoM!E52 -> -0.069767442 | D28: =QoQ!D52 -> 135 | E28: =QoQ!E52 -> 0.48214286 | F28: =YoY!D52 -> 70 | G28: =YoY!E52 -> 0.53846154 | H28: =YTD!D52 -> 440 | I28: =YTD!E52 -> 0.49438202 | J28: ='Budget M'!D52 -> 20 | K28: ='Budget M'!E52 -> 0.11111111 | L28: ='Budget YTD'!D52 -> -30 | M28: ='Budget YTD'!E52 -> -0.022058824 | N28: ='Forecast M'!D52 -> -5 | O28: ='Forecast M'!E52 -> -0.024390244
A29: Total net revenue | B29: =MoM!D53 -> 8.473 | C29: =MoM!E53 -> 0.0042545243 | D29: =QoQ!D53 -> 267.19 | E29: =QoQ!E53 -> 0.071741628 | F29: =YoY!D53 -> 376.381 | G29: =YoY!E53 -> 0.23181608 | H29: =YTD!D53 -> 3135.667 | I29: =YTD!E53 -> 0.26100786 | J29: ='Budget M'!D53 -> -30 | K29: ='Budget M'!E53 -> -0.014778325 | L29: ='Budget YTD'!D53 -> -466.603 | M29: ='Budget YTD'!E53 -> -0.029879883 | N29: ='Forecast M'!D53 -> 0.238 | O29: ='Forecast M'!E53 -> 0.00011901416
A30: Service delivery (subscription COR) | B30: =MoM!D54 -> 25.81282 | C30: =MoM!E54 -> 0.049813699 | D30: =QoQ!D54 -> 56.29645 | E30: =QoQ!E54 -> 0.055966765 | F30: =YoY!D54 -> 129.58282 | G30: =YoY!E54 -> 0.31268689 | H30: =YTD!D54 -> 894.06368 | I30: =YTD!E54 -> 0.28658034 | J30: ='Budget M'!D54 -> -8.46177 | K30: ='Budget M'!E54 -> -0.015316481 | L30: ='Budget YTD'!D54 -> -92.9912 | M30: ='Budget YTD'!E54 -> -0.022643109 | N30: ='Forecast M'!D54 -> 6.61685 | O30: ='Forecast M'!E54 -> 0.012313095
A31: Services delivery (PS COR) | B31: =MoM!D62 -> 0.888 | C31: =MoM!E62 -> 0.0074551682 | D31: =QoQ!D62 -> -0.076 | E31: =QoQ!E62 -> -0.00031774169 | F31: =YoY!D62 -> 16.405 | G31: =YoY!E62 -> 0.15835706 | H31: =YTD!D62 -> 211.416 | I31: =YTD!E62 -> 0.28258429 | J31: ='Budget M'!D62 -> 0.588 | K31: ='Budget M'!E62 -> 0.0049241282 | L31: ='Budget YTD'!D62 -> 0.588 | M31: ='Budget YTD'!E62 -> 0.00061315147 | N31: ='Forecast M'!D62 -> 0.588 | O31: ='Forecast M'!E62 -> 0.0049241282
A32: Total service delivery cost | B32: =MoM!D64 -> 26.70082 | C32: =MoM!E64 -> 0.041896837 | D32: =QoQ!D64 -> 56.22045 | E32: =QoQ!E64 -> 0.045154133 | F32: =YoY!D64 -> 145.98782 | G32: =YoY!E64 -> 0.28182314 | H32: =YTD!D64 -> 1105.4797 | I32: =YTD!E64 -> 0.2858074 | J32: ='Budget M'!D64 -> -7.87377 | K32: ='Budget M'!E64 -> -0.011719121 | L32: ='Budget YTD'!D64 -> -92.4032 | M32: ='Budget YTD'!E64 -> -0.01824059 | N32: ='Forecast M'!D64 -> 7.20485 | O32: ='Forecast M'!E64 -> 0.010969706
A33: Management gross profit | B33: =MoM!D65 -> -18.22782 | C33: =MoM!E65 -> -0.013459936 | D33: =QoQ!D65 -> 210.96955 | E33: =QoQ!E65 -> 0.085093817 | F33: =YoY!D65 -> 230.39318 | G33: =YoY!E65 -> 0.20838618 | H33: =YTD!D65 -> 2030.1873 | I33: =YTD!E65 -> 0.2492321 | J33: ='Budget M'!D65 -> -22.12623 | K33: ='Budget M'!E65 -> -0.016291733 | L33: ='Budget YTD'!D65 -> -374.1998 | M33: ='Budget YTD'!E65 -> -0.035468648 | N33: ='Forecast M'!D65 -> -6.96685 | O33: ='Forecast M'!E65 -> -0.005187656
A34: S&M — direct go-to-market | B34: =MoM!D66 -> -16.2869 | C34: =MoM!E66 -> -0.036010108 | D34: =QoQ!D66 -> 148.6573 | E34: =QoQ!E66 -> 0.20098885 | F34: =YoY!D66 -> 138.0231 | G34: =YoY!E66 -> 0.46320067 | H34: =YTD!D66 -> 865.0437 | I34: =YTD!E66 -> 0.38943175 | J34: ='Budget M'!D66 -> -31.9539 | K34: ='Budget M'!E66 -> -0.06828429 | L34: ='Budget YTD'!D66 -> -184.1209 | M34: ='Budget YTD'!E66 -> -0.056298133 | N34: ='Forecast M'!D66 -> -6.1891 | O34: ='Forecast M'!E66 -> -0.013996501
A35: Contribution after direct go-to-market | B35: =MoM!D72 -> -1.94092 | C35: =MoM!E72 -> -0.002151937 | D35: =QoQ!D72 -> 62.31225 | E35: =QoQ!E72 -> 0.035819282 | F35: =YoY!D72 -> 92.37008 | G35: =YoY!E72 -> 0.11437179 | H35: =YTD!D72 -> 1165.1436 | I35: =YTD!E72 -> 0.19666622 | J35: ='Budget M'!D72 -> 9.82767 | K35: ='Budget M'!E72 -> 0.011040188 | L35: ='Budget YTD'!D72 -> -190.0789 | M35: ='Budget YTD'!E72 -> -0.026110833 | N35: ='Forecast M'!D72 -> -0.77775 | O35: ='Forecast M'!E72 -> -0.00086342053
A36: S&M — shared costs | B36: =MoM!D73 -> 0.81333 | C36: =MoM!E73 -> 0.013741777 | D36: =QoQ!D73 -> 4.87603 | E36: =QoQ!E73 -> 0.042655959 | F36: =YoY!D73 -> 11.09833 | G36: =YoY!E73 -> 0.22695196 | H36: =YTD!D73 -> 90.44073 | I36: =YTD!E73 -> 0.2485187 | J36: ='Budget M'!D73 -> -2.33333 | K36: ='Budget M'!E73 -> -0.037433104 | L36: ='Budget YTD'!D73 -> -18.30665 | M36: ='Budget YTD'!E73 -> -0.038730573 | N36: ='Forecast M'!D73 -> -1.6 | O36: ='Forecast M'!E73 -> -0.025974026
A37: Research and development | B37: =MoM!D77 -> 21.86342 | C37: =MoM!E77 -> 0.054914371 | D37: =QoQ!D77 -> 45.79024 | E37: =QoQ!E77 -> 0.059287185 | F37: =YoY!D77 -> 101.54842 | G37: =YoY!E77 -> 0.31888182 | H37: =YTD!D77 -> 701.30419 | I37: =YTD!E77 -> 0.29172062 | J37: ='Budget M'!D77 -> -36.80167 | K37: ='Budget M'!E77 -> -0.080563782 | L37: ='Budget YTD'!D77 -> -205.56158 | M37: ='Budget YTD'!E77 -> -0.062086454 | N37: ='Forecast M'!D77 -> -8.95375 | O37: ='Forecast M'!E77 -> -0.020873462
A38: General and administrative | B38: =MoM!D83 -> 8.58333 | C38: =MoM!E83 -> 0.044841079 | D38: =QoQ!D83 -> 47.64998 | E38: =QoQ!E83 -> 0.13861139 | F38: =YoY!D83 -> 48.70833 | G38: =YoY!E83 -> 0.32194985 | H38: =YTD!D83 -> 242.1667 | I38: =YTD!E83 -> 0.20542912 | J38: ='Budget M'!D83 -> 4.04167 | K38: ='Budget M'!E83 -> 0.02062515 | L38: ='Budget YTD'!D83 -> -62.16667 | M38: ='Budget YTD'!E83 -> -0.041914824 | N38: ='Forecast M'!D83 -> 19 | O38: ='Forecast M'!E83 -> 0.10497238
A39: Shared S&M, R&D and G&A | B39: =MoM!D87 -> 31.26008 | C39: =MoM!E87 -> 0.048185843 | D39: =QoQ!D87 -> 98.31625 | E39: =QoQ!E87 -> 0.079904388 | F39: =YoY!D87 -> 161.35508 | G39: =YoY!E87 -> 0.31110896 | H39: =YTD!D87 -> 1033.9116 | I39: =YTD!E87 -> 0.26196337 | J39: ='Budget M'!D87 -> -35.09333 | K39: ='Budget M'!E87 -> -0.049075175 | L39: ='Budget YTD'!D87 -> -286.0349 | M39: ='Budget YTD'!E87 -> -0.054309813 | N39: ='Forecast M'!D87 -> 8.44625 | O39: ='Forecast M'!E87 -> 0.012577176
A40: Operating income | B40: =MoM!D88 -> -33.201 | C40: =MoM!E88 -> -0.13112507 | D40: =QoQ!D88 -> -36.004 | E40: =QoQ!E88 -> -0.070706297 | F40: =YoY!D88 -> -68.985 | G40: =YoY!E88 -> -0.23871481 | H40: =YTD!D88 -> 131.232 | I40: =YTD!E88 -> 0.066356103 | J40: ='Budget M'!D88 -> 44.921 | K40: ='Budget M'!E88 -> 0.2565756 | L40: ='Budget YTD'!D88 -> 95.956 | M40: ='Budget YTD'!E88 -> 0.047668891 | N40: ='Forecast M'!D88 -> -9.224 | O40: ='Forecast M'!E88 -> -0.040240114
A41: Interest income | B41: =MoM!D89 -> -1 | C41: =MoM!E89 -> -0.090909091 | D41: =QoQ!D89 -> -1.5 | E41: =QoQ!E89 -> -0.066666667 | F41: =YoY!D89 -> -3 | G41: =YoY!E89 -> -0.23076923 | H41: =YTD!D89 -> -18.5 | I41: =YTD!E89 -> -0.1712963 | J41: ='Budget M'!D89 -> 2 | K41: ='Budget M'!E89 -> 0.25 | L41: ='Budget YTD'!D89 -> 17.5 | M41: ='Budget YTD'!E89 -> 0.24305556 | N41: ='Forecast M'!D89 -> 0 | O41: ='Forecast M'!E89 -> 0
A42: Interest expense | B42: =MoM!D90 -> 0 | C42: =MoM!E90 -> 0 | D42: =QoQ!D90 -> -0.5 | E42: =QoQ!E90 -> -0.0082644628 | F42: =YoY!D90 -> -2 | G42: =YoY!E90 -> -0.0625 | H42: =YTD!D90 -> -17.5 | I42: =YTD!E90 -> -0.067307692 | J42: ='Budget M'!D90 -> 0 | K42: ='Budget M'!E90 -> 0 | L42: ='Budget YTD'!D90 -> -1.5 | M42: ='Budget YTD'!E90 -> -0.006147541 | N42: ='Forecast M'!D90 -> 0 | O42: ='Forecast M'!E90 -> 0
...

Sheet MoM
A1: MoM · Aug 2026 vs Jul 2026
A2: Package MDA-US01-2026-08-001 · US01 · GAAP_PRIMARY · USD thousands · Snapshot SNAP-US01-2026-08-003 · Content hash c33b460e9ec15c44
A3: Approved by J. Patel, Controller · 2026-09-10 · 87 lines in scope, all reviewed · Ledger amounts in blue, formulas in black; GL lines are grouped under the statement lines built from them (use the outline buttons to collapse).
A5: Line | B5: Aug 2026 | C5: Jul 2026 | D5: Variance | E5: % | F5: F/U | G5: Commentary (approved) | H5: Future impacts as of Aug 2026 close | I5: Reviewed | J5: Ties | K5: Ledger current | L5: Ledger comparison
A7: INCOME STATEMENT · accounting view
A8: Subscription revenue | B8: 1800 | C8: 1776.527 | D8: =B8-C8 -> 23.473 | E8: =IF(C8=0,"n/m",D8/ABS(C8)) -> 0.013212859 | F8: =IF(ROUND(D8,5)=0,"",IF(D8>0,"F","U")) -> F | G8: Subscription revenue rose 23.5k (1.3%) vs Jul 2026: new logos (+55.6k; ENT-12, MM-18), partly offset by churned customers (−30.9k; MM-09) and contraction (−12.3k; ENT-04, MM-05); other items (+11.1k). | H8: Later: MM-12 non-renewal notice; subscription ends Sep 30 (Oct on, −29.7k/mo); ENT-12 ramps to contracted MRR in October (Oct on, +22.2k/mo; suggested). Noted at Jul close: ENT-12 goes live in August, partly realized (expected +50.0k, actual +44.5k). | I8: MC · 2026-09-08 | J8: ✓
A9: Professional services revenue | B9: 200 | C9: 215 | D9: =B9-C9 -> -15 | E9: =IF(C9=0,"n/m",D9/ABS(C9)) -> -0.069767442 | F9: =IF(ROUND(D9,5)=0,"",IF(D9>0,"F","U")) -> U | G9: Professional services revenue fell 15.0k (7.0%) vs Jul 2026: P-105 ENT-03 analytics rollout (−60.0k) and P-106 ENT-07 integration (−20.0k), partly offset by P-107 ENT-12 implementation (+45.0k); other items (+20.0k). | H9: Noted at Jul close: P-105 ENT-03 analytics rollout completes in July, realized (expected −60.0k, actual −60.0k). | I9: MC · 2026-09-08 | J9: ✓
A10: Total net revenue | B10: =B8+B9 -> 2000 | C10: =C8+C9 -> 1991.527 | D10: =B10-C10 -> 8.473 | E10: =IF(C10=0,"n/m",D10/ABS(C10)) -> 0.0042545243 | F10: =IF(ROUND(D10,5)=0,"",IF(D10>0,"F","U")) -> F | G10: Total net revenue rose 8.5k (0.4%) vs Jul 2026: new logos (+55.6k; ENT-12, MM-18) and P-107 ENT-12 implementation (+45.0k), partly offset by P-105 ENT-03 analytics rollout (−60.0k); other items (−32.1k). | H10: Later: MM-12 non-renewal notice; subscription ends Sep 30 (Oct on, −29.7k/mo); ENT-12 ramps to contracted MRR in October (Oct on, +22.2k/mo; suggested). | I10: MC · 2026-09-08 | J10: =IF(AND(ROUND(B10-K10,4)=0,ROUND(C10-L10,4)=0,TRUE()),"✓","✗") -> ✓ | K10: 2000 | L10: 1991.527
A11: Cost of revenue — subscription & service delivery | B11: =B12+B13+B14+B15+B16+B17+B18 -> 540 | C11: =C12+C13+C14+C15+C16+C17+C18 -> 514.38718 | D11: =B11-C11 -> 25.61282 | E11: =IF(C11=0,"n/m",D11/ABS(C11)) -> 0.049792882 | F11: =IF(ROUND(D11,5)=0,"",IF(D11<0,"F","U")) -> U | G11: Cost of revenue — subscription & service delivery rose 25.6k (5.0%) vs Jul 2026: pay rate changes (+5.8k), prod (+4.0k) and headcount and mix (+3.8k); other items (+12.0k). | H11: Sep −4.4k: August severance does not recur (−2.1k); August sign-on bonus does not recur (−1.3k); August payroll accrual true-up reverses (−1.0k). Later: Capitalized platform release goes live Oct 1 (Oct on, +1.0k/mo; suggested); Merit cycle effective Jan 1, 2027 (+3.5% of base pay) (Jan on, +9.5k/mo; suggested); and 1 more. | I11: MC · 2026-09-08 | J11: =IF(AND(ROUND(B11-K11,4)=0,ROUND(C11-L11,4)=0,TRUE()),"✓","✗") -> ✓ | K11: 540 | L11: 514.38718
A12: 6100 Cloud hosting · Engineering | B12: 140 | C12: 136 | D12: =B12-C12 -> 4 | E12: =IF(C12=0,"n/m",D12/ABS(C12)) -> 0.029411765 | F12: =IF(ROUND(D12,5)=0,"",IF(D12<0,"F","U")) -> U | G12: Cloud hosting (Engineering) rose 4.0k (2.9%) vs Jul 2026: prod (+4.0k). | I12: Not required | J12: ✓
A13: 6000 Compensation · Engineering | B13: 100 | C13: 93.01775 | D13: =B13-C13 -> 6.98225 | E13: =IF(C13=0,"n/m",D13/ABS(C13)) -> 0.07506363 | F13: =IF(ROUND(D13,5)=0,"",IF(D13<0,"F","U")) -> U | G13: Compensation (Engineering) rose 7.0k (7.5%) vs Jul 2026: hires (+4.1k) and the mix of roles (+2.2k), partly offset by departures (−4.1k); other items (+4.8k). | H13: Sep −2.3k: August sign-on bonus does not recur (−1.3k); August payroll accrual true-up reverses (−1.0k). Later: Merit cycle effective Jan 1, 2027 (+3.5% of base pay) (Jan on, +2.9k/mo; suggested). | I13: Not required | J13: ✓
A14: 6000 Compensation · Customer Success | B14: 84 | C14: 88.5871 | D14: =B14-C14 -> -4.5871 | E14: =IF(C14=0,"n/m",D14/ABS(C14)) -> -0.051780677 | F14: =IF(ROUND(D14,5)=0,"",IF(D14<0,"F","U")) -> F | G14: Compensation (Customer Success) fell 4.6k (5.2%) vs Jul 2026: departures (−7.4k), partly offset by one-time compensation (+2.1k) and benefits and payroll taxes (+0.7k). | H14: Sep −2.1k: August severance does not recur (−2.1k). Later: Merit cycle effective Jan 1, 2027 (+3.5% of base pay) (Jan on, +2.3k/mo; suggested). | I14: Not required | J14: ✓
A15: 6000 Compensation · Support | B15: 160 | C15: 144.269 | D15: =B15-C15 -> 15.731 | E15: =IF(C15=0,"n/m",D15/ABS(C15)) -> 0.10903936 | F15: =IF(ROUND(D15,5)=0,"",IF(D15<0,"F","U")) -> U | G15: Compensation (Support) rose 15.7k (10.9%) vs Jul 2026: hires (+9.0k), pay rate changes (+5.1k) and benefits and payroll taxes (+1.6k). | H15: Later: Merit cycle effective Jan 1, 2027 (+3.5% of base pay) (Jan on, +4.3k/mo; suggested). Noted at Jul close: Support market adjustment effective Aug 1 (+4% of base), realized (expected +5.0k, actual +5.1k). | I15: MC · 2026-09-08 | J15: ✓
A16: 6200 Software & IT services · Corporate IT | B16: 16 | C16: 13.68 | D16: =B16-C16 -> 2.32 | E16: =IF(C16=0,"n/m",D16/ABS(C16)) -> 0.16959064 | F16: =IF(ROUND(D16,5)=0,"",IF(D16<0,"F","U")) -> U | G16: Software & IT services (Corporate IT) rose 2.3k (17.0%) vs Jul 2026: a shift in IT seat allocation (+1.6k) and identity & security (+0.7k). Contract: new SSO/identity platform, start Aug 1, 2026, 12-month term. | H16: Later: Identity platform price step-up in month 7 (Feb on, +0.2k/mo; suggested). Noted at Jul close: Collaboration suite renewal credit in August, missed (expected −3.0k, actual 0.0k). | I16: Not required | J16: ✓
A17: 6700 Depreciation & amortization · Shared assets | B17: 20 | C17: 19.33333 | D17: =B17-C17 -> 0.66667 | E17: =IF(C17=0,"n/m",D17/ABS(C17)) -> 0.034482937 | F17: =IF(ROUND(D17,5)=0,"",IF(D17<0,"F","U")) -> U | G17: Depreciation & amortization (Shared assets) rose 0.7k (3.4%) vs Jul 2026: servers & hardware (+0.7k). Asset register: production server expansion placed in service Aug 3. | H17: Later: Capitalized platform release goes live Oct 1 (Oct on, +1.0k/mo; suggested). | I17: Not required | J17: ✓
A18: 6800 Stock-based compensation · Company pool | B18: 20 | C18: 19.5 | D18: =B18-C18 -> 0.5 | E18: =IF(C18=0,"n/m",D18/ABS(C18)) -> 0.025641026 | F18: =IF(ROUND(D18,5)=0,"",IF(D18<0,"F","U")) -> U | G18: Stock-based compensation (Company pool) rose 0.5k (2.6%) vs Jul 2026: 2026 refresh grants (+0.5k). | I18: Not required | J18: ✓
A19: Cost of revenue — professional services | B19: 120 | C19: 119.112 | D19: =B19-C19 -> 0.888 | E19: =IF(C19=0,"n/m",D19/ABS(C19)) -> 0.0074551682 | F19: =IF(ROUND(D19,5)=0,"",IF(D19<0,"F","U")) -> U | G19: Cost of revenue — professional services rose 0.9k (0.7%) vs Jul 2026: benefits and payroll taxes (+0.9k). | H19: Later: Merit cycle effective Jan 1, 2027 (+3.5% of base pay) (Jan on, +3.4k/mo; suggested). | I19: Not required | J19: ✓
A20: Total cost of revenue | B20: =B11+B19 -> 660 | C20: =C11+C19 -> 633.49918 | D20: =B20-C20 -> 26.50082 | E20: =IF(C20=0,"n/m",D20/ABS(C20)) -> 0.041832446 | F20: =IF(ROUND(D20,5)=0,"",IF(D20<0,"F","U")) -> U | G20: Total cost of revenue rose 26.5k (4.2%) vs Jul 2026: pay rate changes (+5.8k), prod (+4.0k) and headcount and mix (+3.9k); other items (+12.8k). | H20: Sep −4.4k: August severance does not recur (−2.1k); August sign-on bonus does not recur (−1.3k); August payroll accrual true-up reverses (−1.0k). Later: Capitalized platform release goes live Oct 1 (Oct on, +1.0k/mo; suggested); Merit cycle effective Jan 1, 2027 (+3.5% of base pay) (Jan on, +12.8k/mo; suggested); and 1 more. | I20: MC · 2026-09-08 | J20: =IF(AND(ROUND(B20-K20,4)=0,ROUND(C20-L20,4)=0,TRUE()),"✓","✗") -> ✓ | K20: 660 | L20: 633.49918
A21: Gross profit | B21: =B10-B20 -> 1340 | C21: =C10-C20 -> 1358.0278 | D21: =B21-C21 -> -18.02782 | E21: =IF(C21=0,"n/m",D21/ABS(C21)) -> -0.013275001 | F21: =IF(ROUND(D21,5)=0,"",IF(D21>0,"F","U")) -> U | G21: Gross profit fell 18.0k (1.3%) vs Jul 2026: higher cost of revenue (−26.5k), partly offset by higher net revenue (+8.5k). | H21: Sep +4.4k: August severance does not recur (+2.1k); August sign-on bonus does not recur (+1.3k); August payroll accrual true-up reverses (+1.0k). Later: MM-12 non-renewal notice; subscription ends Sep 30 (Oct on, −29.7k/mo); ENT-12 ramps to contracted MRR in October (Oct on, +22.2k/mo; suggested); and 3 more. | I21: MC · 2026-09-08 | J21: =IF(AND(ROUND(B21-K21,4)=0,ROUND(C21-L21,4)=0,TRUE()),"✓","✗") -> ✓ | K21: 1340 | L21: 1358.0278
A22: Research and development | B22: =B23+B24+B25+B26+B27 -> 414 | C22: =C23+C24+C25+C26+C27 -> 392.43658 | D22: =B22-C22 -> 21.56342 | E22: =IF(C22=0,"n/m",D22/ABS(C22)) -> 0.054947528 | F22: =IF(ROUND(D22,5)=0,"",IF(D22<0,"F","U")) -> U | G22: Research and development rose 21.6k (5.5%) vs Jul 2026: headcount and mix (+6.7k), partial-month timing (+5.5k) and one-time compensation (+3.8k); other items (+5.6k). | H22: Sep −6.8k: August sign-on bonus does not recur (−3.8k); August payroll accrual true-up reverses (−3.0k). Later: Capitalized platform release goes live Oct 1 (Oct on, +1.0k/mo; suggested); Merit cycle effective Jan 1, 2027 (+3.5% of base pay) (Jan on, +8.7k/mo; suggested); and 1 more. | I22: MC · 2026-09-08 | J22: =IF(AND(ROUND(B22-K22,4)=0,ROUND(C22-L22,4)=0,TRUE()),"✓","✗") -> ✓ | K22: 414 | L22: 392.43658
A23: 6000 Compensation · Engineering | B23: 300 | C23: 279.05325 | D23: =B23-C23 -> 20.94675 | E23: =IF(C23=0,"n/m",D23/ABS(C23)) -> 0.07506363 | F23: =IF(ROUND(D23,5)=0,"",IF(D23<0,"F","U")) -> U | G23: Compensation (Engineering) rose 20.9k (7.5%) vs Jul 2026: hires (+12.4k) and the mix of roles (+6.7k), partly offset by departures (−12.5k); other items (+14.3k). | H23: Sep −6.8k: August sign-on bonus does not recur (−3.8k); August payroll accrual true-up reverses (−3.0k). Later: Merit cycle effective Jan 1, 2027 (+3.5% of base pay) (Jan on, +8.7k/mo; suggested). | I23: MC · 2026-09-08 | J23: ✓
A24: 6100 Cloud hosting · Engineering | B24: 40 | C24: 42 | D24: =B24-C24 -> -2 | E24: =IF(C24=0,"n/m",D24/ABS(C24)) -> -0.047619048 | F24: =IF(ROUND(D24,5)=0,"",IF(D24<0,"F","U")) -> F | G24: Cloud hosting (Engineering) fell 2.0k (4.8%) vs Jul 2026: dev-test (−2.0k). | I24: Not required | J24: ✓
A25: 6200 Software & IT services · Corporate IT | B25: 24 | C25: 22.8 | D25: =B25-C25 -> 1.2 | E25: =IF(C25=0,"n/m",D25/ABS(C25)) -> 0.052631579 | F25: =IF(ROUND(D25,5)=0,"",IF(D25<0,"F","U")) -> U | G25: Software & IT services (Corporate IT) rose 1.2k (5.3%) vs Jul 2026: identity & security (+1.2k). Contract: new SSO/identity platform, start Aug 1, 2026, 12-month term. | H25: Later: Identity platform price step-up in month 7 (Feb on, +0.3k/mo; suggested). Noted at Jul close: Collaboration suite renewal credit in August, missed (expected −3.0k, actual 0.0k). | I25: Not required | J25: ✓
A26: 6700 Depreciation & amortization · Shared assets | B26: 20 | C26: 19.33333 | D26: =B26-C26 -> 0.66667 | E26: =IF(C26=0,"n/m",D26/ABS(C26)) -> 0.034482937 | F26: =IF(ROUND(D26,5)=0,"",IF(D26<0,"F","U")) -> U | G26: Depreciation & amortization (Shared assets) rose 0.7k (3.4%) vs Jul 2026: servers & hardware (+0.7k). Asset register: production server expansion placed in service Aug 3. | H26: Later: Capitalized platform release goes live Oct 1 (Oct on, +1.0k/mo; suggested). | I26: Not required | J26: ✓
A27: 6800 Stock-based compensation · Company pool | B27: 30 | C27: 29.25 | D27: =B27-C27 -> 0.75 | E27: =IF(C27=0,"n/m",D27/ABS(C27)) -> 0.025641026 | F27: =IF(ROUND(D27,5)=0,"",IF(D27<0,"F","U")) -> U | G27: Stock-based compensation (Company pool) rose 0.8k (2.6%) vs Jul 2026: 2026 refresh grants (+0.8k). | I27: Not required | J27: ✓
A28: Sales and marketing | B28: =B29+B30+B31+B32+B33+B34+B35+B36 -> 490 | C28: =C29+C30+C31+C32+C33+C34+C35+C36 -> 505.77357 | D28: =B28-C28 -> -15.77357 | E28: =IF(C28=0,"n/m",D28/ABS(C28)) -> -0.031187019 | F28: =IF(ROUND(D28,5)=0,"",IF(D28<0,"F","U")) -> F | G28: Sales and marketing fell 15.8k (3.1%) vs Jul 2026: events & conferences (−55.0k), partly offset by partner marketing (+10.0k) and demo (+10.0k); other items (+19.2k). Journal memo: annual customer conference (Jul 21–23). | H28: Sep −10.9k: Partner Summit demo clusters wind down (−10.0k; suggested); August severance does not recur (−0.9k). Later: Q4 user conference deposits (Oct–Nov, +75.0k total); Capitalized platform release goes live Oct 1 (Oct on, +0.5k/mo; suggested); and 2 more. | I28: MC · 2026-09-08 | J28: =IF(AND(ROUND(B28-K28,4)=0,ROUND(C28-L28,4)=0,TRUE()),"✓","✗") -> ✓ | K28: 490 | L28: 505.77357
A29: 6000 Compensation · Sales | B29: 240 | C29: 225.321 | D29: =B29-C29 -> 14.679 | E29: =IF(C29=0,"n/m",D29/ABS(C29)) -> 0.065147057 | F29: =IF(ROUND(D29,5)=0,"",IF(D29<0,"F","U")) -> U | G29: Compensation (Sales) rose 14.7k (6.5%) vs Jul 2026: hires (+13.0k) and the mix of roles (+9.0k), partly offset by departures (−13.0k); other items (+5.7k). | H29: Later: Merit cycle effective Jan 1, 2027 (+3.5% of base pay) (Jan on, +6.8k/mo; suggested). Noted at Jul close: Two account executives start in August, realized (expected +13.0k, actual +13.0k). | I29: MC · 2026-09-08 | J29: ✓
A30: 6000 Compensation · Customer Success | B30: 36 | C30: 37.9659 | D30: =B30-C30 -> -1.9659 | E30: =IF(C30=0,"n/m",D30/ABS(C30)) -> -0.051780677 | F30: =IF(ROUND(D30,5)=0,"",IF(D30<0,"F","U")) -> F | G30: Compensation (Customer Success) fell 2.0k (5.2%) vs Jul 2026: departures (−3.2k), partly offset by one-time compensation (+0.9k) and benefits and payroll taxes (+0.3k). | H30: Sep −0.9k: August severance does not recur (−0.9k). Later: Merit cycle effective Jan 1, 2027 (+3.5% of base pay) (Jan on, +1.0k/mo; suggested). | I30: Not required | J30: ✓
A31: 6300 Marketing programs · Marketing | B31: 100 | C31: 140 | D31: =B31-C31 -> -40 | E31: =IF(C31=0,"n/m",D31/ABS(C31)) -> -0.28571429 | F31: =IF(ROUND(D31,5)=0,"",IF(D31<0,"F","U")) -> F | G31: Marketing programs (Marketing) fell 40.0k (28.6%) vs Jul 2026: events & conferences (−55.0k), partly offset by partner marketing (+10.0k) and paid search & social (+3.0k); other items (+2.0k). Journal memo: annual customer conference (Jul 21–23). | H31: Later: Q4 user conference deposits (Oct–Nov, +75.0k total). Noted at Jul close: July customer conference does not recur in August, realized (expected −55.0k, actual −55.0k); Paid search pilot paused in August, missed (expected −3.0k, actual +3.0k). | I31: MC · 2026-09-08 | J31: ✓
A32: 6410 Amortization of capitalized commissions · Sales | B32: 40 | C32: 39 | D32: =B32-C32 -> 1 | E32: =IF(C32=0,"n/m",D32/ABS(C32)) -> 0.025641026 | F32: =IF(ROUND(D32,5)=0,"",IF(D32<0,"F","U")) -> U | G32: Amortization of capitalized commissions (Sales) rose 1.0k (2.6%) vs Jul 2026: FY26 H2 cohort (+1.0k). | I32: Not required | J32: ✓
A33: 6100 Cloud hosting · Engineering | B33: 20 | C33: 10 | D33: =B33-C33 -> 10 | E33: =IF(C33=0,"n/m",D33/ABS(C33)) -> 1 | F33: =IF(ROUND(D33,5)=0,"",IF(D33<0,"F","U")) -> U | G33: Cloud hosting (Engineering) rose 10.0k (100.0%) vs Jul 2026: demo (+10.0k). Invoice memo: demo clusters for Partner Summit (Aug 12–14). | H33: Sep −10.0k: Partner Summit demo clusters wind down (−10.0k; suggested). | I33: MC · 2026-09-08 | J33: ✓
A34: 6200 Software & IT services · Corporate IT | B34: 24 | C34: 24.32 | D34: =B34-C34 -> -0.32 | E34: =IF(C34=0,"n/m",D34/ABS(C34)) -> -0.013157895 | F34: =IF(ROUND(D34,5)=0,"",IF(D34<0,"F","U")) -> F | G34: Software & IT services (Corporate IT) fell 0.3k (1.3%) vs Jul 2026: a shift in IT seat allocation (−1.6k), partly offset by identity & security (+1.3k). Contract: new SSO/identity platform, start Aug 1, 2026, 12-month term. | H34: Later: Identity platform price step-up in month 7 (Feb on, +0.3k/mo; suggested). Noted at Jul close: Collaboration suite renewal credit in August, missed (expected −3.0k, actual 0.0k). | I34: Not required | J34: ✓
A35: 6700 Depreciation & amortization · Shared assets | B35: 10 | C35: 9.66667 | D35: =B35-C35 -> 0.33333 | E35: =IF(C35=0,"n/m",D35/ABS(C35)) -> 0.034482402 | F35: =IF(ROUND(D35,5)=0,"",IF(D35<0,"F","U")) -> U | G35: Depreciation & amortization (Shared assets) rose 0.3k (3.4%) vs Jul 2026: servers & hardware (+0.3k). Asset register: production server expansion placed in service Aug 3. | H35: Later: Capitalized platform release goes live Oct 1 (Oct on, +0.5k/mo; suggested). | I35: Not required | J35: ✓
A36: 6800 Stock-based compensation · Company pool | B36: 20 | C36: 19.5 | D36: =B36-C36 -> 0.5 | E36: =IF(C36=0,"n/m",D36/ABS(C36)) -> 0.025641026 | F36: =IF(ROUND(D36,5)=0,"",IF(D36<0,"F","U")) -> U | G36: Stock-based compensation (Company pool) rose 0.5k (2.6%) vs Jul 2026: 2026 refresh grants (+0.5k). | I36: Not required | J36: ✓
A37: General and administrative | B37: =B38+B39+B40+B41 -> 216 | C37: =C38+C39+C40+C41 -> 206.61667 | D37: =B37-C37 -> 9.38333 | E37: =IF(C37=0,"n/m",D37/ABS(C37)) -> 0.045414196 | F37: =IF(ROUND(D37,5)=0,"",IF(D37<0,"F","U")) -> U | G37: General and administrative rose 9.4k (4.5%) vs Jul 2026: outside legal (+8.0k) and a journal without a category (JE-2026-08-114; +3.0k), partly offset by audit & tax fees (−5.0k); other items (+3.4k). Matter: enterprise renewal contract reviews. | H37: Later: Capitalized platform release goes live Oct 1 (Oct on, +0.5k/mo; suggested); FY2026 audit fieldwork (Dec–Jan, +43.0k total); and 1 more. | I37: MC · 2026-09-08 | J37: =IF(AND(ROUND(B37-K37,4)=0,ROUND(C37-L37,4)=0,TRUE()),"✓","✗") -> ✓ | K37: 216 | L37: 206.61667
A38: 6050 Corporate labor & professional services · G&A | B38: 180 | C38: 172 | D38: =B38-C38 -> 8 | E38: =IF(C38=0,"n/m",D38/ABS(C38)) -> 0.046511628 | F38: =IF(ROUND(D38,5)=0,"",IF(D38<0,"F","U")) -> U | G38: Corporate labor & professional services (G&A) rose 8.0k (4.7%) vs Jul 2026: outside legal (+8.0k) and a journal without a category (JE-2026-08-114; +3.0k), partly offset by audit & tax fees (−5.0k); other items (+2.0k). Matter: enterprise renewal contract reviews. Reviewer: JE-2026-08-114 is the August outside-legal accrual true-up; it has been recategorized to outside legal. | H38: Later: FY2026 audit fieldwork (Dec–Jan, +43.0k total). Noted at Jul close: Q2 review accrual reverses in August, partly realized (expected −8.0k, actual −5.0k). | I38: Not required | J38: ✓
A39: 6200 Software & IT services · Corporate IT | B39: 16 | C39: 15.2 | D39: =B39-C39 -> 0.8 | E39: =IF(C39=0,"n/m",D39/ABS(C39)) -> 0.052631579 | F39: =IF(ROUND(D39,5)=0,"",IF(D39<0,"F","U")) -> U | G39: Software & IT services (Corporate IT) rose 0.8k (5.3%) vs Jul 2026: identity & security (+0.8k). Contract: new SSO/identity platform, start Aug 1, 2026, 12-month term. | H39: Later: Identity platform price step-up in month 7 (Feb on, +0.2k/mo; suggested). Noted at Jul close: Collaboration suite renewal credit in August, missed (expected −3.0k, actual 0.0k). | I39: Not required | J39: ✓
A40: 6700 Depreciation & amortization · Shared assets | B40: 10 | C40: 9.66667 | D40: =B40-C40 -> 0.33333 | E40: =IF(C40=0,"n/m",D40/ABS(C40)) -> 0.034482402 | F40: =IF(ROUND(D40,5)=0,"",IF(D40<0,"F","U")) -> U | G40: Depreciation & amortization (Shared assets) rose 0.3k (3.4%) vs Jul 2026: servers & hardware (+0.3k). Asset register: production server expansion placed in service Aug 3. | H40: Later: Capitalized platform release goes live Oct 1 (Oct on, +0.5k/mo; suggested). | I40: Not required | J40: ✓
A41: 6800 Stock-based compensation · Company pool | B41: 10 | C41: 9.75 | D41: =B41-C41 -> 0.25 | E41: =IF(C41=0,"n/m",D41/ABS(C41)) -> 0.025641026 | F41: =IF(ROUND(D41,5)=0,"",IF(D41<0,"F","U")) -> U | G41: Stock-based compensation (Company pool) rose 0.3k (2.6%) vs Jul 2026: 2026 refresh grants (+0.3k). | I41: Not required | J41: ✓
A42: Total operating expenses | B42: =B22+B28+B37 -> 1120 | C42: =C22+C28+C37 -> 1104.8268 | D42: =B42-C42 -> 15.17318 | E42: =IF(C42=0,"n/m",D42/ABS(C42)) -> 0.013733537 | F42: =IF(ROUND(D42,5)=0,"",IF(D42<0,"F","U")) -> U | G42: Total operating expenses rose 15.2k (1.4%) vs Jul 2026: research and development (+21.6k) and general and administrative (+9.4k), partly offset by sales and marketing (−15.8k). | H42: Sep −17.7k: Partner Summit demo clusters wind down (−10.0k; suggested); August sign-on bonus does not recur (−3.8k); August payroll accrual true-up reverses (−3.0k); and 1 more. Later: Capitalized platform release goes live Oct 1 (Oct on, +2.0k/mo; suggested); Q4 user conference deposits (Oct–Nov, +75.0k total); and 3 more. | I42: MC · 2026-09-08 | J42: =IF(AND(ROUND(B42-K42,4)=0,ROUND(C42-L42,4)=0,TRUE()),"✓","✗") -> ✓ | K42: 1120 | L42: 1104.8268
...

Sheet QoQ
A1: QoQ · Q3 2026 QTD vs prior quarter (same months)
A2: Package MDA-US01-2026-08-001 · US01 · GAAP_PRIMARY · USD thousands · Snapshot SNAP-US01-2026-08-003 · Content hash c33b460e9ec15c44
A3: Approved by J. Patel, Controller · 2026-09-10 · 97 lines in scope, all reviewed · Ledger amounts in blue, formulas in black; GL lines are grouped under the statement lines built from them (use the outline buttons to collapse).
A5: Line | B5: Jul–Aug 2026 | C5: Apr–May 2026 | D5: Variance | E5: % | F5: F/U | G5: Commentary (approved) | H5: Future impacts as of Aug 2026 close | I5: Reviewed | J5: Ties | K5: Ledger current | L5: Ledger comparison
A7: INCOME STATEMENT · accounting view
A8: Subscription revenue | B8: 3576.527 | C8: 3444.337 | D8: =B8-C8 -> 132.19 | E8: =IF(C8=0,"n/m",D8/ABS(C8)) -> 0.038378939 | F8: =IF(ROUND(D8,5)=0,"",IF(D8>0,"F","U")) -> F | G8: Subscription revenue rose 132.2k (3.8%) vs the same months of the prior quarter: new logos (+122.3k; MM-17, ENT-12) and expansion at existing customers (+67.9k), partly offset by contraction (−43.2k; MM-09, ENT-04); other items (−14.8k). | H8: Later: MM-12 non-renewal notice; subscription ends Sep 30 (Oct on, −29.7k/mo); ENT-12 ramps to contracted MRR in October (Oct on, +22.2k/mo; suggested). Noted at Jul close: ENT-12 goes live in August, partly realized (expected +50.0k, actual +44.5k). | I8: MC · 2026-09-09 | J8: ✓
A9: Professional services revenue | B9: 415 | C9: 280 | D9: =B9-C9 -> 135 | E9: =IF(C9=0,"n/m",D9/ABS(C9)) -> 0.48214286 | F9: =IF(ROUND(D9,5)=0,"",IF(D9>0,"F","U")) -> F | G9: Professional services revenue rose 135.0k (48.2%) vs the same months of the prior quarter: P-107 ENT-12 implementation (+125.0k) and P-106 ENT-07 integration (+50.0k), partly offset by P-105 ENT-03 analytics rollout (−60.0k); other items (+20.0k). | H9: Noted at Jul close: P-105 ENT-03 analytics rollout completes in July, realized (expected −60.0k, actual −60.0k). | I9: MC · 2026-09-09 | J9: ✓
A10: Total net revenue | B10: =B8+B9 -> 3991.527 | C10: =C8+C9 -> 3724.337 | D10: =B10-C10 -> 267.19 | E10: =IF(C10=0,"n/m",D10/ABS(C10)) -> 0.071741628 | F10: =IF(ROUND(D10,5)=0,"",IF(D10>0,"F","U")) -> F | G10: Total net revenue rose 267.2k (7.2%) vs the same months of the prior quarter: P-107 ENT-12 implementation (+125.0k), new logos (+122.3k; MM-17, ENT-12) and expansion at existing customers (+68.0k); other items (−48.1k). | H10: Later: MM-12 non-renewal notice; subscription ends Sep 30 (Oct on, −29.7k/mo); ENT-12 ramps to contracted MRR in October (Oct on, +22.2k/mo; suggested). | I10: MC · 2026-09-09 | J10: =IF(AND(ROUND(B10-K10,4)=0,ROUND(C10-L10,4)=0,TRUE()),"✓","✗") -> ✓ | K10: 3991.527 | L10: 3724.337
A11: Cost of revenue — subscription & service delivery | B11: =B12+B13+B14+B15+B16+B17+B18 -> 1054.3872 | C11: =C12+C13+C14+C15+C16+C17+C18 -> 998.65073 | D11: =B11-C11 -> 55.73645 | E11: =IF(C11=0,"n/m",D11/ABS(C11)) -> 0.055811755 | F11: =IF(ROUND(D11,5)=0,"",IF(D11<0,"F","U")) -> U | G11: Cost of revenue — subscription & service delivery rose 55.7k (5.6%) vs the same months of the prior quarter: prod (+24.4k), base pay (+14.1k) and benefits (+3.8k); other items (+13.4k). | H11: Sep −4.4k: August severance does not recur (−2.1k); August sign-on bonus does not recur (−1.3k); August payroll accrual true-up reverses (−1.0k). Later: Capitalized platform release goes live Oct 1 (Oct on, +1.0k/mo; suggested); Merit cycle effective Jan 1, 2027 (+3.5% of base pay) (Jan on, +9.5k/mo; suggested); and 1 more. | I11: MC · 2026-09-09 | J11: =IF(AND(ROUND(B11-K11,4)=0,ROUND(C11-L11,4)=0,TRUE()),"✓","✗") -> ✓ | K11: 1054.3872 | L11: 998.65073
A12: 6100 Cloud hosting · Engineering | B12: 276 | C12: 249.1 | D12: =B12-C12 -> 26.9 | E12: =IF(C12=0,"n/m",D12/ABS(C12)) -> 0.10798876 | F12: =IF(ROUND(D12,5)=0,"",IF(D12<0,"F","U")) -> U | G12: Cloud hosting (Engineering) rose 26.9k (10.8%) vs the same months of the prior quarter: prod (+24.4k), staging (prod-adjacent) (+2.0k) and shared observability (+0.5k). | I12: MC · 2026-09-09 | J12: ✓
A13: 6000 Compensation · Engineering | B13: 193.01775 | C13: 183.071 | D13: =B13-C13 -> 9.94675 | E13: =IF(C13=0,"n/m",D13/ABS(C13)) -> 0.054332745 | F13: =IF(ROUND(D13,5)=0,"",IF(D13<0,"F","U")) -> U | G13: Compensation (Engineering) rose 9.9k (5.4%) vs the same months of the prior quarter: base pay (+8.2k), benefits (+1.1k) and GL vs payroll reconciling (+0.5k); other items (+0.1k). | H13: Sep −2.3k: August sign-on bonus does not recur (−1.3k); August payroll accrual true-up reverses (−1.0k). Later: Merit cycle effective Jan 1, 2027 (+3.5% of base pay) (Jan on, +2.9k/mo; suggested). | I13: Not required | J13: ✓
A14: 6000 Compensation · Customer Success | B14: 172.5871 | C14: 177.8784 | D14: =B14-C14 -> -5.2913 | E14: =IF(C14=0,"n/m",D14/ABS(C14)) -> -0.029746726 | F14: =IF(ROUND(D14,5)=0,"",IF(D14<0,"F","U")) -> F | G14: Compensation (Customer Success) fell 5.3k (3.0%) vs the same months of the prior quarter: base pay (−5.9k) and employer payroll taxes (−1.2k), partly offset by one-time compensation (+2.1k); other items (−0.3k). | H14: Sep −2.1k: August severance does not recur (−2.1k). Later: Merit cycle effective Jan 1, 2027 (+3.5% of base pay) (Jan on, +2.3k/mo; suggested). | I14: Not required | J14: ✓
A15: 6000 Compensation · Support | B15: 304.269 | C15: 289.652 | D15: =B15-C15 -> 14.617 | E15: =IF(C15=0,"n/m",D15/ABS(C15)) -> 0.050464005 | F15: =IF(ROUND(D15,5)=0,"",IF(D15<0,"F","U")) -> U | G15: Compensation (Support) rose 14.6k (5.0%) vs the same months of the prior quarter: base pay (+11.7k) and benefits (+3.1k), partly offset by employer payroll taxes (−0.2k). | H15: Later: Merit cycle effective Jan 1, 2027 (+3.5% of base pay) (Jan on, +4.3k/mo; suggested). Noted at Jul close: Support market adjustment effective Aug 1 (+4% of base), realized (expected +5.0k, actual +5.1k). | I15: MC · 2026-09-09 | J15: ✓
