Workbook

Sheet Summary Comparison

Sheet Budget Summary
B1: Budget | C1: Budget | D1: Budget | E1: Budget | F1: Budget | G1: Budget | H1: Budget | I1: Budget | J1: Budget | K1: Budget | L1: Budget | M1: Budget | O1: Budget | P1: Budget | Q1: Budget | R1: Budget | T1: Budget
A2: Spending | B2: Q1 | C2: Q1 | D2: Q1 | E2: Q2 | F2: Q2 | G2: Q2 | H2: Q3 | I2: Q3 | J2: Q3 | K2: Q4 | L2: Q4 | M2: Q4
A3: marketing_channel | B3: 2026-01 | C3: 2026-02 | D3: 2026-03 | E3: 2026-04 | F3: 2026-05 | G3: 2026-06 | H3: 2026-07 | I3: 2026-08 | J3: 2026-09 | K3: 2026-10 | L3: 2026-11 | M3: 2026-12 | O3: Q1 | P3: Q2 | Q3: Q3 | R3: Q4 | T3: FY26
A4: Paid Search | B4: =SUMIFS(Budget_marketing_pipeline!$J:$J,Budget_marketing_pipeline!$D:$D,'Budget Summary'!$A4,Budget_marketing_pipeline!$C:$C,'Budget Summary'!B$3) -> 119854.26 | C4: =SUMIFS(Budget_marketing_pipeline!$J:$J,Budget_marketing_pipeline!$D:$D,'Budget Summary'!$A4,Budget_marketing_pipeline!$C:$C,'Budget Summary'!C$3) -> 225376.12 | D4: =SUMIFS(Budget_marketing_pipeline!$J:$J,Budget_marketing_pipeline!$D:$D,'Budget Summary'!$A4,Budget_marketing_pipeline!$C:$C,'Budget Summary'!D$3) -> 147063.74 | E4: =SUMIFS(Budget_marketing_pipeline!$J:$J,Budget_marketing_pipeline!$D:$D,'Budget Summary'!$A4,Budget_marketing_pipeline!$C:$C,'Budget Summary'!E$3) -> 313308.47 | F4: =SUMIFS(Budget_marketing_pipeline!$J:$J,Budget_marketing_pipeline!$D:$D,'Budget Summary'!$A4,Budget_marketing_pipeline!$C:$C,'Budget Summary'!F$3) -> 175679.04 | G4: =SUMIFS(Budget_marketing_pipeline!$J:$J,Budget_marketing_pipeline!$D:$D,'Budget Summary'!$A4,Budget_marketing_pipeline!$C:$C,'Budget Summary'!G$3) -> 252801.57 | H4: =SUMIFS(Budget_marketing_pipeline!$J:$J,Budget_marketing_pipeline!$D:$D,'Budget Summary'!$A4,Budget_marketing_pipeline!$C:$C,'Budget Summary'!H$3) -> 110408.61 | I4: =SUMIFS(Budget_marketing_pipeline!$J:$J,Budget_marketing_pipeline!$D:$D,'Budget Summary'!$A4,Budget_marketing_pipeline!$C:$C,'Budget Summary'!I$3) -> 262671.51 | ... M4: =SUMIFS(Budget_marketing_pipeline!$J:$J,Budget_marketing_pipeline!$D:$D,'Budget Summary'!$A4,Budget_marketing_pipeline!$C:$C,'Budget Summary'!M$3) -> 149056.22 | O4: =SUMIFS($B4:$M4,$B$2:$M$2,O$3) -> 492294.12 | P4: =SUMIFS($B4:$M4,$B$2:$M$2,P$3) -> 741789.08 | Q4: =SUMIFS($B4:$M4,$B$2:$M$2,Q$3) -> 532772.5 | R4: =SUMIFS($B4:$M4,$B$2:$M$2,R$3) -> 338878.9 | T4: =SUM(O4:R4) -> 2105734.6
A5: Paid Social | B5: =SUMIFS(Budget_marketing_pipeline!$J:$J,Budget_marketing_pipeline!$D:$D,'Budget Summary'!$A5,Budget_marketing_pipeline!$C:$C,'Budget Summary'!B$3) -> 153150.62 | C5: =SUMIFS(Budget_marketing_pipeline!$J:$J,Budget_marketing_pipeline!$D:$D,'Budget Summary'!$A5,Budget_marketing_pipeline!$C:$C,'Budget Summary'!C$3) -> 45477.59 | D5: =SUMIFS(Budget_marketing_pipeline!$J:$J,Budget_marketing_pipeline!$D:$D,'Budget Summary'!$A5,Budget_marketing_pipeline!$C:$C,'Budget Summary'!D$3) -> 208865.88 | E5: =SUMIFS(Budget_marketing_pipeline!$J:$J,Budget_marketing_pipeline!$D:$D,'Budget Summary'!$A5,Budget_marketing_pipeline!$C:$C,'Budget Summary'!E$3) -> 265825.9 | F5: =SUMIFS(Budget_marketing_pipeline!$J:$J,Budget_marketing_pipeline!$D:$D,'Budget Summary'!$A5,Budget_marketing_pipeline!$C:$C,'Budget Summary'!F$3) -> 121733.74 | G5: =SUMIFS(Budget_marketing_pipeline!$J:$J,Budget_marketing_pipeline!$D:$D,'Budget Summary'!$A5,Budget_marketing_pipeline!$C:$C,'Budget Summary'!G$3) -> 67656.32 | H5: =SUMIFS(Budget_marketing_pipeline!$J:$J,Budget_marketing_pipeline!$D:$D,'Budget Summary'!$A5,Budget_marketing_pipeline!$C:$C,'Budget Summary'!H$3) -> 174632.31 | I5: =SUMIFS(Budget_marketing_pipeline!$J:$J,Budget_marketing_pipeline!$D:$D,'Budget Summary'!$A5,Budget_marketing_pipeline!$C:$C,'Budget Summary'!I$3) -> 112923.21 | ... M5: =SUMIFS(Budget_marketing_pipeline!$J:$J,Budget_marketing_pipeline!$D:$D,'Budget Summary'!$A5,Budget_marketing_pipeline!$C:$C,'Budget Summary'!M$3) -> 59227.8 | O5: =SUMIFS($B5:$M5,$B$2:$M$2,O$3) -> 407494.09 | P5: =SUMIFS($B5:$M5,$B$2:$M$2,P$3) -> 455215.96 | Q5: =SUMIFS($B5:$M5,$B$2:$M$2,Q$3) -> 355615.33 | R5: =SUMIFS($B5:$M5,$B$2:$M$2,R$3) -> 277038.81 | T5: =SUM(O5:R5) -> 1495364.2
A6: Organic Search | B6: =SUMIFS(Budget_marketing_pipeline!$J:$J,Budget_marketing_pipeline!$D:$D,'Budget Summary'!$A6,Budget_marketing_pipeline!$C:$C,'Budget Summary'!B$3) -> 156837.96 | C6: =SUMIFS(Budget_marketing_pipeline!$J:$J,Budget_marketing_pipeline!$D:$D,'Budget Summary'!$A6,Budget_marketing_pipeline!$C:$C,'Budget Summary'!C$3) -> 218418.4 | D6: =SUMIFS(Budget_marketing_pipeline!$J:$J,Budget_marketing_pipeline!$D:$D,'Budget Summary'!$A6,Budget_marketing_pipeline!$C:$C,'Budget Summary'!D$3) -> 133280.94 | E6: =SUMIFS(Budget_marketing_pipeline!$J:$J,Budget_marketing_pipeline!$D:$D,'Budget Summary'!$A6,Budget_marketing_pipeline!$C:$C,'Budget Summary'!E$3) -> 68355.64 | F6: =SUMIFS(Budget_marketing_pipeline!$J:$J,Budget_marketing_pipeline!$D:$D,'Budget Summary'!$A6,Budget_marketing_pipeline!$C:$C,'Budget Summary'!F$3) -> 136215.07 | G6: =SUMIFS(Budget_marketing_pipeline!$J:$J,Budget_marketing_pipeline!$D:$D,'Budget Summary'!$A6,Budget_marketing_pipeline!$C:$C,'Budget Summary'!G$3) -> 157268.95 | H6: =SUMIFS(Budget_marketing_pipeline!$J:$J,Budget_marketing_pipeline!$D:$D,'Budget Summary'!$A6,Budget_marketing_pipeline!$C:$C,'Budget Summary'!H$3) -> 97209.05 | I6: =SUMIFS(Budget_marketing_pipeline!$J:$J,Budget_marketing_pipeline!$D:$D,'Budget Summary'!$A6,Budget_marketing_pipeline!$C:$C,'Budget Summary'!I$3) -> 93368.45 | ... M6: =SUMIFS(Budget_marketing_pipeline!$J:$J,Budget_marketing_pipeline!$D:$D,'Budget Summary'!$A6,Budget_marketing_pipeline!$C:$C,'Budget Summary'!M$3) -> 139652.43 | O6: =SUMIFS($B6:$M6,$B$2:$M$2,O$3) -> 508537.3 | P6: =SUMIFS($B6:$M6,$B$2:$M$2,P$3) -> 361839.66 | Q6: =SUMIFS($B6:$M6,$B$2:$M$2,Q$3) -> 452651.46 | R6: =SUMIFS($B6:$M6,$B$2:$M$2,R$3) -> 475902.11 | T6: =SUM(O6:R6) -> 1798930.5
A7: Partner | B7: =SUMIFS(Budget_marketing_pipeline!$J:$J,Budget_marketing_pipeline!$D:$D,'Budget Summary'!$A7,Budget_marketing_pipeline!$C:$C,'Budget Summary'!B$3) -> 99640.66 | C7: =SUMIFS(Budget_marketing_pipeline!$J:$J,Budget_marketing_pipeline!$D:$D,'Budget Summary'!$A7,Budget_marketing_pipeline!$C:$C,'Budget Summary'!C$3) -> 328585.82 | D7: =SUMIFS(Budget_marketing_pipeline!$J:$J,Budget_marketing_pipeline!$D:$D,'Budget Summary'!$A7,Budget_marketing_pipeline!$C:$C,'Budget Summary'!D$3) -> 106696.77 | E7: =SUMIFS(Budget_marketing_pipeline!$J:$J,Budget_marketing_pipeline!$D:$D,'Budget Summary'!$A7,Budget_marketing_pipeline!$C:$C,'Budget Summary'!E$3) -> 135354.25 | F7: =SUMIFS(Budget_marketing_pipeline!$J:$J,Budget_marketing_pipeline!$D:$D,'Budget Summary'!$A7,Budget_marketing_pipeline!$C:$C,'Budget Summary'!F$3) -> 71483.13 | G7: =SUMIFS(Budget_marketing_pipeline!$J:$J,Budget_marketing_pipeline!$D:$D,'Budget Summary'!$A7,Budget_marketing_pipeline!$C:$C,'Budget Summary'!G$3) -> 268720.4 | H7: =SUMIFS(Budget_marketing_pipeline!$J:$J,Budget_marketing_pipeline!$D:$D,'Budget Summary'!$A7,Budget_marketing_pipeline!$C:$C,'Budget Summary'!H$3) -> 273851.79 | I7: =SUMIFS(Budget_marketing_pipeline!$J:$J,Budget_marketing_pipeline!$D:$D,'Budget Summary'!$A7,Budget_marketing_pipeline!$C:$C,'Budget Summary'!I$3) -> 190299.52 | ... M7: =SUMIFS(Budget_marketing_pipeline!$J:$J,Budget_marketing_pipeline!$D:$D,'Budget Summary'!$A7,Budget_marketing_pipeline!$C:$C,'Budget Summary'!M$3) -> 135389.08 | O7: =SUMIFS($B7:$M7,$B$2:$M$2,O$3) -> 534923.25 | P7: =SUMIFS($B7:$M7,$B$2:$M$2,P$3) -> 475557.78 | Q7: =SUMIFS($B7:$M7,$B$2:$M$2,Q$3) -> 585970.32 | R7: =SUMIFS($B7:$M7,$B$2:$M$2,R$3) -> 558649.25 | T7: =SUM(O7:R7) -> 2155100.6
A8: Webinar | B8: =SUMIFS(Budget_marketing_pipeline!$J:$J,Budget_marketing_pipeline!$D:$D,'Budget Summary'!$A8,Budget_marketing_pipeline!$C:$C,'Budget Summary'!B$3) -> 23296.59 | C8: =SUMIFS(Budget_marketing_pipeline!$J:$J,Budget_marketing_pipeline!$D:$D,'Budget Summary'!$A8,Budget_marketing_pipeline!$C:$C,'Budget Summary'!C$3) -> 109176.4 | D8: =SUMIFS(Budget_marketing_pipeline!$J:$J,Budget_marketing_pipeline!$D:$D,'Budget Summary'!$A8,Budget_marketing_pipeline!$C:$C,'Budget Summary'!D$3) -> 58808 | E8: =SUMIFS(Budget_marketing_pipeline!$J:$J,Budget_marketing_pipeline!$D:$D,'Budget Summary'!$A8,Budget_marketing_pipeline!$C:$C,'Budget Summary'!E$3) -> 214667.53 | F8: =SUMIFS(Budget_marketing_pipeline!$J:$J,Budget_marketing_pipeline!$D:$D,'Budget Summary'!$A8,Budget_marketing_pipeline!$C:$C,'Budget Summary'!F$3) -> 186604.32 | G8: =SUMIFS(Budget_marketing_pipeline!$J:$J,Budget_marketing_pipeline!$D:$D,'Budget Summary'!$A8,Budget_marketing_pipeline!$C:$C,'Budget Summary'!G$3) -> 50351.47 | H8: =SUMIFS(Budget_marketing_pipeline!$J:$J,Budget_marketing_pipeline!$D:$D,'Budget Summary'!$A8,Budget_marketing_pipeline!$C:$C,'Budget Summary'!H$3) -> 135263.45 | I8: =SUMIFS(Budget_marketing_pipeline!$J:$J,Budget_marketing_pipeline!$D:$D,'Budget Summary'!$A8,Budget_marketing_pipeline!$C:$C,'Budget Summary'!I$3) -> 197031.09 | ... M8: =SUMIFS(Budget_marketing_pipeline!$J:$J,Budget_marketing_pipeline!$D:$D,'Budget Summary'!$A8,Budget_marketing_pipeline!$C:$C,'Budget Summary'!M$3) -> 81476.56 | O8: =SUMIFS($B8:$M8,$B$2:$M$2,O$3) -> 191280.99 | P8: =SUMIFS($B8:$M8,$B$2:$M$2,P$3) -> 451623.32 | Q8: =SUMIFS($B8:$M8,$B$2:$M$2,Q$3) -> 473369.14 | R8: =SUMIFS($B8:$M8,$B$2:$M$2,R$3) -> 259815.23 | T8: =SUM(O8:R8) -> 1376088.7
A9: Field Event | B9: =SUMIFS(Budget_marketing_pipeline!$J:$J,Budget_marketing_pipeline!$D:$D,'Budget Summary'!$A9,Budget_marketing_pipeline!$C:$C,'Budget Summary'!B$3) -> 124159.28 | C9: =SUMIFS(Budget_marketing_pipeline!$J:$J,Budget_marketing_pipeline!$D:$D,'Budget Summary'!$A9,Budget_marketing_pipeline!$C:$C,'Budget Summary'!C$3) -> 165485.13 | D9: =SUMIFS(Budget_marketing_pipeline!$J:$J,Budget_marketing_pipeline!$D:$D,'Budget Summary'!$A9,Budget_marketing_pipeline!$C:$C,'Budget Summary'!D$3) -> 91391.72 | E9: =SUMIFS(Budget_marketing_pipeline!$J:$J,Budget_marketing_pipeline!$D:$D,'Budget Summary'!$A9,Budget_marketing_pipeline!$C:$C,'Budget Summary'!E$3) -> 51779.83 | F9: =SUMIFS(Budget_marketing_pipeline!$J:$J,Budget_marketing_pipeline!$D:$D,'Budget Summary'!$A9,Budget_marketing_pipeline!$C:$C,'Budget Summary'!F$3) -> 279309.21 | G9: =SUMIFS(Budget_marketing_pipeline!$J:$J,Budget_marketing_pipeline!$D:$D,'Budget Summary'!$A9,Budget_marketing_pipeline!$C:$C,'Budget Summary'!G$3) -> 195157.26 | H9: =SUMIFS(Budget_marketing_pipeline!$J:$J,Budget_marketing_pipeline!$D:$D,'Budget Summary'!$A9,Budget_marketing_pipeline!$C:$C,'Budget Summary'!H$3) -> 73668.51 | I9: =SUMIFS(Budget_marketing_pipeline!$J:$J,Budget_marketing_pipeline!$D:$D,'Budget Summary'!$A9,Budget_marketing_pipeline!$C:$C,'Budget Summary'!I$3) -> 175601.2 | ... M9: =SUMIFS(Budget_marketing_pipeline!$J:$J,Budget_marketing_pipeline!$D:$D,'Budget Summary'!$A9,Budget_marketing_pipeline!$C:$C,'Budget Summary'!M$3) -> 72954.4 | O9: =SUMIFS($B9:$M9,$B$2:$M$2,O$3) -> 381036.13 | P9: =SUMIFS($B9:$M9,$B$2:$M$2,P$3) -> 526246.3 | Q9: =SUMIFS($B9:$M9,$B$2:$M$2,Q$3) -> 567476.58 | R9: =SUMIFS($B9:$M9,$B$2:$M$2,R$3) -> 410903.36 | T9: =SUM(O9:R9) -> 1885662.4
A10: Referral | B10: =SUMIFS(Budget_marketing_pipeline!$J:$J,Budget_marketing_pipeline!$D:$D,'Budget Summary'!$A10,Budget_marketing_pipeline!$C:$C,'Budget Summary'!B$3) -> 157604.62 | C10: =SUMIFS(Budget_marketing_pipeline!$J:$J,Budget_marketing_pipeline!$D:$D,'Budget Summary'!$A10,Budget_marketing_pipeline!$C:$C,'Budget Summary'!C$3) -> 153525.13 | D10: =SUMIFS(Budget_marketing_pipeline!$J:$J,Budget_marketing_pipeline!$D:$D,'Budget Summary'!$A10,Budget_marketing_pipeline!$C:$C,'Budget Summary'!D$3) -> 251581.54 | E10: =SUMIFS(Budget_marketing_pipeline!$J:$J,Budget_marketing_pipeline!$D:$D,'Budget Summary'!$A10,Budget_marketing_pipeline!$C:$C,'Budget Summary'!E$3) -> 99946.4 | F10: =SUMIFS(Budget_marketing_pipeline!$J:$J,Budget_marketing_pipeline!$D:$D,'Budget Summary'!$A10,Budget_marketing_pipeline!$C:$C,'Budget Summary'!F$3) -> 215451.19 | G10: =SUMIFS(Budget_marketing_pipeline!$J:$J,Budget_marketing_pipeline!$D:$D,'Budget Summary'!$A10,Budget_marketing_pipeline!$C:$C,'Budget Summary'!G$3) -> 297414.53 | H10: =SUMIFS(Budget_marketing_pipeline!$J:$J,Budget_marketing_pipeline!$D:$D,'Budget Summary'!$A10,Budget_marketing_pipeline!$C:$C,'Budget Summary'!H$3) -> 286237.13 | I10: =SUMIFS(Budget_marketing_pipeline!$J:$J,Budget_marketing_pipeline!$D:$D,'Budget Summary'!$A10,Budget_marketing_pipeline!$C:$C,'Budget Summary'!I$3) -> 82481.99 | ... M10: =SUMIFS(Budget_marketing_pipeline!$J:$J,Budget_marketing_pipeline!$D:$D,'Budget Summary'!$A10,Budget_marketing_pipeline!$C:$C,'Budget Summary'!M$3) -> 267053.02 | O10: =SUMIFS($B10:$M10,$B$2:$M$2,O$3) -> 562711.29 | P10: =SUMIFS($B10:$M10,$B$2:$M$2,P$3) -> 612812.12 | Q10: =SUMIFS($B10:$M10,$B$2:$M$2,Q$3) -> 629386.88 | R10: =SUMIFS($B10:$M10,$B$2:$M$2,R$3) -> 568616.41 | T10: =SUM(O10:R10) -> 2373526.7
A11: Direct | B11: =SUMIFS(Budget_marketing_pipeline!$J:$J,Budget_marketing_pipeline!$D:$D,'Budget Summary'!$A11,Budget_marketing_pipeline!$C:$C,'Budget Summary'!B$3) -> 74267.49 | C11: =SUMIFS(Budget_marketing_pipeline!$J:$J,Budget_marketing_pipeline!$D:$D,'Budget Summary'!$A11,Budget_marketing_pipeline!$C:$C,'Budget Summary'!C$3) -> 97835.91 | D11: =SUMIFS(Budget_marketing_pipeline!$J:$J,Budget_marketing_pipeline!$D:$D,'Budget Summary'!$A11,Budget_marketing_pipeline!$C:$C,'Budget Summary'!D$3) -> 109612.81 | E11: =SUMIFS(Budget_marketing_pipeline!$J:$J,Budget_marketing_pipeline!$D:$D,'Budget Summary'!$A11,Budget_marketing_pipeline!$C:$C,'Budget Summary'!E$3) -> 77863.58 | F11: =SUMIFS(Budget_marketing_pipeline!$J:$J,Budget_marketing_pipeline!$D:$D,'Budget Summary'!$A11,Budget_marketing_pipeline!$C:$C,'Budget Summary'!F$3) -> 242542.44 | G11: =SUMIFS(Budget_marketing_pipeline!$J:$J,Budget_marketing_pipeline!$D:$D,'Budget Summary'!$A11,Budget_marketing_pipeline!$C:$C,'Budget Summary'!G$3) -> 131532.89 | H11: =SUMIFS(Budget_marketing_pipeline!$J:$J,Budget_marketing_pipeline!$D:$D,'Budget Summary'!$A11,Budget_marketing_pipeline!$C:$C,'Budget Summary'!H$3) -> 74148.71 | I11: =SUMIFS(Budget_marketing_pipeline!$J:$J,Budget_marketing_pipeline!$D:$D,'Budget Summary'!$A11,Budget_marketing_pipeline!$C:$C,'Budget Summary'!I$3) -> 203008.51 | ... M11: =SUMIFS(Budget_marketing_pipeline!$J:$J,Budget_marketing_pipeline!$D:$D,'Budget Summary'!$A11,Budget_marketing_pipeline!$C:$C,'Budget Summary'!M$3) -> 113386.66 | O11: =SUMIFS($B11:$M11,$B$2:$M$2,O$3) -> 281716.21 | P11: =SUMIFS($B11:$M11,$B$2:$M$2,P$3) -> 451938.91 | Q11: =SUMIFS($B11:$M11,$B$2:$M$2,Q$3) -> 392898.59 | R11: =SUMIFS($B11:$M11,$B$2:$M$2,R$3) -> 428141.59 | T11: =SUM(O11:R11) -> 1554695.3
A12: Content Syndication | B12: =SUMIFS(Budget_marketing_pipeline!$J:$J,Budget_marketing_pipeline!$D:$D,'Budget Summary'!$A12,Budget_marketing_pipeline!$C:$C,'Budget Summary'!B$3) -> 71910.24 | C12: =SUMIFS(Budget_marketing_pipeline!$J:$J,Budget_marketing_pipeline!$D:$D,'Budget Summary'!$A12,Budget_marketing_pipeline!$C:$C,'Budget Summary'!C$3) -> 136485.64 | D12: =SUMIFS(Budget_marketing_pipeline!$J:$J,Budget_marketing_pipeline!$D:$D,'Budget Summary'!$A12,Budget_marketing_pipeline!$C:$C,'Budget Summary'!D$3) -> 71870.35 | E12: =SUMIFS(Budget_marketing_pipeline!$J:$J,Budget_marketing_pipeline!$D:$D,'Budget Summary'!$A12,Budget_marketing_pipeline!$C:$C,'Budget Summary'!E$3) -> 100912.24 | F12: =SUMIFS(Budget_marketing_pipeline!$J:$J,Budget_marketing_pipeline!$D:$D,'Budget Summary'!$A12,Budget_marketing_pipeline!$C:$C,'Budget Summary'!F$3) -> 94222.59 | G12: =SUMIFS(Budget_marketing_pipeline!$J:$J,Budget_marketing_pipeline!$D:$D,'Budget Summary'!$A12,Budget_marketing_pipeline!$C:$C,'Budget Summary'!G$3) -> 173294.63 | H12: =SUMIFS(Budget_marketing_pipeline!$J:$J,Budget_marketing_pipeline!$D:$D,'Budget Summary'!$A12,Budget_marketing_pipeline!$C:$C,'Budget Summary'!H$3) -> 242621.21 | I12: =SUMIFS(Budget_marketing_pipeline!$J:$J,Budget_marketing_pipeline!$D:$D,'Budget Summary'!$A12,Budget_marketing_pipeline!$C:$C,'Budget Summary'!I$3) -> 136000.33 | ... M12: =SUMIFS(Budget_marketing_pipeline!$J:$J,Budget_marketing_pipeline!$D:$D,'Budget Summary'!$A12,Budget_marketing_pipeline!$C:$C,'Budget Summary'!M$3) -> 235500.65 | O12: =SUMIFS($B12:$M12,$B$2:$M$2,O$3) -> 280266.23 | P12: =SUMIFS($B12:$M12,$B$2:$M$2,P$3) -> 368429.46 | Q12: =SUMIFS($B12:$M12,$B$2:$M$2,Q$3) -> 503306.77 | R12: =SUMIFS($B12:$M12,$B$2:$M$2,R$3) -> 655741.57 | T12: =SUM(O12:R12) -> 1807744
A13: Outbound | B13: =SUMIFS(Budget_marketing_pipeline!$J:$J,Budget_marketing_pipeline!$D:$D,'Budget Summary'!$A13,Budget_marketing_pipeline!$C:$C,'Budget Summary'!B$3) -> 66111.34 | C13: =SUMIFS(Budget_marketing_pipeline!$J:$J,Budget_marketing_pipeline!$D:$D,'Budget Summary'!$A13,Budget_marketing_pipeline!$C:$C,'Budget Summary'!C$3) -> 54991.97 | D13: =SUMIFS(Budget_marketing_pipeline!$J:$J,Budget_marketing_pipeline!$D:$D,'Budget Summary'!$A13,Budget_marketing_pipeline!$C:$C,'Budget Summary'!D$3) -> 271057.86 | E13: =SUMIFS(Budget_marketing_pipeline!$J:$J,Budget_marketing_pipeline!$D:$D,'Budget Summary'!$A13,Budget_marketing_pipeline!$C:$C,'Budget Summary'!E$3) -> 228055.47 | F13: =SUMIFS(Budget_marketing_pipeline!$J:$J,Budget_marketing_pipeline!$D:$D,'Budget Summary'!$A13,Budget_marketing_pipeline!$C:$C,'Budget Summary'!F$3) -> 170604.14 | G13: =SUMIFS(Budget_marketing_pipeline!$J:$J,Budget_marketing_pipeline!$D:$D,'Budget Summary'!$A13,Budget_marketing_pipeline!$C:$C,'Budget Summary'!G$3) -> 209653.88 | H13: =SUMIFS(Budget_marketing_pipeline!$J:$J,Budget_marketing_pipeline!$D:$D,'Budget Summary'!$A13,Budget_marketing_pipeline!$C:$C,'Budget Summary'!H$3) -> 84111.14 | I13: =SUMIFS(Budget_marketing_pipeline!$J:$J,Budget_marketing_pipeline!$D:$D,'Budget Summary'!$A13,Budget_marketing_pipeline!$C:$C,'Budget Summary'!I$3) -> 461546.2 | ... M13: =SUMIFS(Budget_marketing_pipeline!$J:$J,Budget_marketing_pipeline!$D:$D,'Budget Summary'!$A13,Budget_marketing_pipeline!$C:$C,'Budget Summary'!M$3) -> 146392.2 | O13: =SUMIFS($B13:$M13,$B$2:$M$2,O$3) -> 392161.17 | P13: =SUMIFS($B13:$M13,$B$2:$M$2,P$3) -> 608313.49 | Q13: =SUMIFS($B13:$M13,$B$2:$M$2,Q$3) -> 722463.42 | R13: =SUMIFS($B13:$M13,$B$2:$M$2,R$3) -> 341355.22 | T13: =SUM(O13:R13) -> 2064293.3
A14: Customer Success | B14: =SUMIFS(Budget_marketing_pipeline!$J:$J,Budget_marketing_pipeline!$D:$D,'Budget Summary'!$A14,Budget_marketing_pipeline!$C:$C,'Budget Summary'!B$3) -> 0 | C14: =SUMIFS(Budget_marketing_pipeline!$J:$J,Budget_marketing_pipeline!$D:$D,'Budget Summary'!$A14,Budget_marketing_pipeline!$C:$C,'Budget Summary'!C$3) -> 0 | D14: =SUMIFS(Budget_marketing_pipeline!$J:$J,Budget_marketing_pipeline!$D:$D,'Budget Summary'!$A14,Budget_marketing_pipeline!$C:$C,'Budget Summary'!D$3) -> 0 | E14: =SUMIFS(Budget_marketing_pipeline!$J:$J,Budget_marketing_pipeline!$D:$D,'Budget Summary'!$A14,Budget_marketing_pipeline!$C:$C,'Budget Summary'!E$3) -> 0 | F14: =SUMIFS(Budget_marketing_pipeline!$J:$J,Budget_marketing_pipeline!$D:$D,'Budget Summary'!$A14,Budget_marketing_pipeline!$C:$C,'Budget Summary'!F$3) -> 0 | G14: =SUMIFS(Budget_marketing_pipeline!$J:$J,Budget_marketing_pipeline!$D:$D,'Budget Summary'!$A14,Budget_marketing_pipeline!$C:$C,'Budget Summary'!G$3) -> 0 | H14: =SUMIFS(Budget_marketing_pipeline!$J:$J,Budget_marketing_pipeline!$D:$D,'Budget Summary'!$A14,Budget_marketing_pipeline!$C:$C,'Budget Summary'!H$3) -> 0 | I14: =SUMIFS(Budget_marketing_pipeline!$J:$J,Budget_marketing_pipeline!$D:$D,'Budget Summary'!$A14,Budget_marketing_pipeline!$C:$C,'Budget Summary'!I$3) -> 0 | ... M14: =SUMIFS(Budget_marketing_pipeline!$J:$J,Budget_marketing_pipeline!$D:$D,'Budget Summary'!$A14,Budget_marketing_pipeline!$C:$C,'Budget Summary'!M$3) -> 0 | O14: =SUMIFS($B14:$M14,$B$2:$M$2,O$3) -> 0 | P14: =SUMIFS($B14:$M14,$B$2:$M$2,P$3) -> 0 | Q14: =SUMIFS($B14:$M14,$B$2:$M$2,Q$3) -> 0 | R14: =SUMIFS($B14:$M14,$B$2:$M$2,R$3) -> 0 | T14: =SUM(O14:R14) -> 0
A15: Total | B15: =SUM(B4:B14) -> 1046833.1 | C15: =SUM(C4:C14) -> 1535358.1 | D15: =SUM(D4:D14) -> 1450229.6 | E15: =SUM(E4:E14) -> 1556069.3 | F15: =SUM(F4:F14) -> 1693844.9 | G15: =SUM(G4:G14) -> 1803851.9 | H15: =SUM(H4:H14) -> 1552151.9 | I15: =SUM(I4:I14) -> 1914932 | ... M15: =SUM(M4:M14) -> 1400089 | O15: =SUMIFS($B15:$M15,$B$2:$M$2,O$3) -> 4032420.8 | P15: =SUMIFS($B15:$M15,$B$2:$M$2,P$3) -> 5053766.1 | Q15: =SUMIFS($B15:$M15,$B$2:$M$2,Q$3) -> 5215911 | R15: =SUMIFS($B15:$M15,$B$2:$M$2,R$3) -> 4315042.4 | T15: =SUM(O15:R15) -> 18617140
A17: MQL | B17: Q1 | C17: Q1 | D17: Q1 | E17: Q2 | F17: Q2 | G17: Q2 | H17: Q3 | I17: Q3 | J17: Q3 | K17: Q4 | L17: Q4 | M17: Q4
A18: marketing_channel | B18: 2026-01 | C18: 2026-02 | D18: 2026-03 | E18: 2026-04 | F18: 2026-05 | G18: 2026-06 | H18: 2026-07 | I18: 2026-08 | J18: 2026-09 | K18: 2026-10 | L18: 2026-11 | M18: 2026-12 | O18: Q1 | P18: Q2 | Q18: Q3 | R18: Q4 | T18: FY26
A19: Paid Search | B19: =SUMIFS(Budget_marketing_pipeline!$E:$E,Budget_marketing_pipeline!$D:$D,'Budget Summary'!$A19,Budget_marketing_pipeline!$C:$C,'Budget Summary'!B$3) -> 560 | C19: =SUMIFS(Budget_marketing_pipeline!$E:$E,Budget_marketing_pipeline!$D:$D,'Budget Summary'!$A19,Budget_marketing_pipeline!$C:$C,'Budget Summary'!C$3) -> 932 | D19: =SUMIFS(Budget_marketing_pipeline!$E:$E,Budget_marketing_pipeline!$D:$D,'Budget Summary'!$A19,Budget_marketing_pipeline!$C:$C,'Budget Summary'!D$3) -> 741 | E19: =SUMIFS(Budget_marketing_pipeline!$E:$E,Budget_marketing_pipeline!$D:$D,'Budget Summary'!$A19,Budget_marketing_pipeline!$C:$C,'Budget Summary'!E$3) -> 978 | F19: =SUMIFS(Budget_marketing_pipeline!$E:$E,Budget_marketing_pipeline!$D:$D,'Budget Summary'!$A19,Budget_marketing_pipeline!$C:$C,'Budget Summary'!F$3) -> 927 | G19: =SUMIFS(Budget_marketing_pipeline!$E:$E,Budget_marketing_pipeline!$D:$D,'Budget Summary'!$A19,Budget_marketing_pipeline!$C:$C,'Budget Summary'!G$3) -> 1027 | H19: =SUMIFS(Budget_marketing_pipeline!$E:$E,Budget_marketing_pipeline!$D:$D,'Budget Summary'!$A19,Budget_marketing_pipeline!$C:$C,'Budget Summary'!H$3) -> 562 | I19: =SUMIFS(Budget_marketing_pipeline!$E:$E,Budget_marketing_pipeline!$D:$D,'Budget Summary'!$A19,Budget_marketing_pipeline!$C:$C,'Budget Summary'!I$3) -> 934 | ... M19: =SUMIFS(Budget_marketing_pipeline!$E:$E,Budget_marketing_pipeline!$D:$D,'Budget Summary'!$A19,Budget_marketing_pipeline!$C:$C,'Budget Summary'!M$3) -> 1148 | O19: =SUMIFS($B19:$M19,$B$2:$M$2,O$3) -> 2233 | P19: =SUMIFS($B19:$M19,$B$2:$M$2,P$3) -> 2932 | Q19: =SUMIFS($B19:$M19,$B$2:$M$2,Q$3) -> 2106 | R19: =SUMIFS($B19:$M19,$B$2:$M$2,R$3) -> 2948 | T19: =SUM(O19:R19) -> 10219
A20: Paid Social | B20: =SUMIFS(Budget_marketing_pipeline!$E:$E,Budget_marketing_pipeline!$D:$D,'Budget Summary'!$A20,Budget_marketing_pipeline!$C:$C,'Budget Summary'!B$3) -> 875 | C20: =SUMIFS(Budget_marketing_pipeline!$E:$E,Budget_marketing_pipeline!$D:$D,'Budget Summary'!$A20,Budget_marketing_pipeline!$C:$C,'Budget Summary'!C$3) -> 448 | D20: =SUMIFS(Budget_marketing_pipeline!$E:$E,Budget_marketing_pipeline!$D:$D,'Budget Summary'!$A20,Budget_marketing_pipeline!$C:$C,'Budget Summary'!D$3) -> 1534 | E20: =SUMIFS(Budget_marketing_pipeline!$E:$E,Budget_marketing_pipeline!$D:$D,'Budget Summary'!$A20,Budget_marketing_pipeline!$C:$C,'Budget Summary'!E$3) -> 1406 | F20: =SUMIFS(Budget_marketing_pipeline!$E:$E,Budget_marketing_pipeline!$D:$D,'Budget Summary'!$A20,Budget_marketing_pipeline!$C:$C,'Budget Summary'!F$3) -> 574 | G20: =SUMIFS(Budget_marketing_pipeline!$E:$E,Budget_marketing_pipeline!$D:$D,'Budget Summary'!$A20,Budget_marketing_pipeline!$C:$C,'Budget Summary'!G$3) -> 288 | H20: =SUMIFS(Budget_marketing_pipeline!$E:$E,Budget_marketing_pipeline!$D:$D,'Budget Summary'!$A20,Budget_marketing_pipeline!$C:$C,'Budget Summary'!H$3) -> 571 | I20: =SUMIFS(Budget_marketing_pipeline!$E:$E,Budget_marketing_pipeline!$D:$D,'Budget Summary'!$A20,Budget_marketing_pipeline!$C:$C,'Budget Summary'!I$3) -> 493 | ... M20: =SUMIFS(Budget_marketing_pipeline!$E:$E,Budget_marketing_pipeline!$D:$D,'Budget Summary'!$A20,Budget_marketing_pipeline!$C:$C,'Budget Summary'!M$3) -> 649 | O20: =SUMIFS($B20:$M20,$B$2:$M$2,O$3) -> 2857 | P20: =SUMIFS($B20:$M20,$B$2:$M$2,P$3) -> 2268 | Q20: =SUMIFS($B20:$M20,$B$2:$M$2,Q$3) -> 1633 | R20: =SUMIFS($B20:$M20,$B$2:$M$2,R$3) -> 2159 | T20: =SUM(O20:R20) -> 8917
A21: Organic Search | B21: =SUMIFS(Budget_marketing_pipeline!$E:$E,Budget_marketing_pipeline!$D:$D,'Budget Summary'!$A21,Budget_marketing_pipeline!$C:$C,'Budget Summary'!B$3) -> 1290 | C21: =SUMIFS(Budget_marketing_pipeline!$E:$E,Budget_marketing_pipeline!$D:$D,'Budget Summary'!$A21,Budget_marketing_pipeline!$C:$C,'Budget Summary'!C$3) -> 1078 | D21: =SUMIFS(Budget_marketing_pipeline!$E:$E,Budget_marketing_pipeline!$D:$D,'Budget Summary'!$A21,Budget_marketing_pipeline!$C:$C,'Budget Summary'!D$3) -> 666 | E21: =SUMIFS(Budget_marketing_pipeline!$E:$E,Budget_marketing_pipeline!$D:$D,'Budget Summary'!$A21,Budget_marketing_pipeline!$C:$C,'Budget Summary'!E$3) -> 484 | F21: =SUMIFS(Budget_marketing_pipeline!$E:$E,Budget_marketing_pipeline!$D:$D,'Budget Summary'!$A21,Budget_marketing_pipeline!$C:$C,'Budget Summary'!F$3) -> 1083 | G21: =SUMIFS(Budget_marketing_pipeline!$E:$E,Budget_marketing_pipeline!$D:$D,'Budget Summary'!$A21,Budget_marketing_pipeline!$C:$C,'Budget Summary'!G$3) -> 917 | H21: =SUMIFS(Budget_marketing_pipeline!$E:$E,Budget_marketing_pipeline!$D:$D,'Budget Summary'!$A21,Budget_marketing_pipeline!$C:$C,'Budget Summary'!H$3) -> 628 | I21: =SUMIFS(Budget_marketing_pipeline!$E:$E,Budget_marketing_pipeline!$D:$D,'Budget Summary'!$A21,Budget_marketing_pipeline!$C:$C,'Budget Summary'!I$3) -> 580 | ... M21: =SUMIFS(Budget_marketing_pipeline!$E:$E,Budget_marketing_pipeline!$D:$D,'Budget Summary'!$A21,Budget_marketing_pipeline!$C:$C,'Budget Summary'!M$3) -> 1016 | O21: =SUMIFS($B21:$M21,$B$2:$M$2,O$3) -> 3034 | P21: =SUMIFS($B21:$M21,$B$2:$M$2,P$3) -> 2484 | Q21: =SUMIFS($B21:$M21,$B$2:$M$2,Q$3) -> 2525 | R21: =SUMIFS($B21:$M21,$B$2:$M$2,R$3) -> 2782 | T21: =SUM(O21:R21) -> 10825
A22: Partner | B22: =SUMIFS(Budget_marketing_pipeline!$E:$E,Budget_marketing_pipeline!$D:$D,'Budget Summary'!$A22,Budget_marketing_pipeline!$C:$C,'Budget Summary'!B$3) -> 907 | C22: =SUMIFS(Budget_marketing_pipeline!$E:$E,Budget_marketing_pipeline!$D:$D,'Budget Summary'!$A22,Budget_marketing_pipeline!$C:$C,'Budget Summary'!C$3) -> 1188 | D22: =SUMIFS(Budget_marketing_pipeline!$E:$E,Budget_marketing_pipeline!$D:$D,'Budget Summary'!$A22,Budget_marketing_pipeline!$C:$C,'Budget Summary'!D$3) -> 495 | E22: =SUMIFS(Budget_marketing_pipeline!$E:$E,Budget_marketing_pipeline!$D:$D,'Budget Summary'!$A22,Budget_marketing_pipeline!$C:$C,'Budget Summary'!E$3) -> 844 | F22: =SUMIFS(Budget_marketing_pipeline!$E:$E,Budget_marketing_pipeline!$D:$D,'Budget Summary'!$A22,Budget_marketing_pipeline!$C:$C,'Budget Summary'!F$3) -> 336 | G22: =SUMIFS(Budget_marketing_pipeline!$E:$E,Budget_marketing_pipeline!$D:$D,'Budget Summary'!$A22,Budget_marketing_pipeline!$C:$C,'Budget Summary'!G$3) -> 645 | H22: =SUMIFS(Budget_marketing_pipeline!$E:$E,Budget_marketing_pipeline!$D:$D,'Budget Summary'!$A22,Budget_marketing_pipeline!$C:$C,'Budget Summary'!H$3) -> 1233 | I22: =SUMIFS(Budget_marketing_pipeline!$E:$E,Budget_marketing_pipeline!$D:$D,'Budget Summary'!$A22,Budget_marketing_pipeline!$C:$C,'Budget Summary'!I$3) -> 519 | ... M22: =SUMIFS(Budget_marketing_pipeline!$E:$E,Budget_marketing_pipeline!$D:$D,'Budget Summary'!$A22,Budget_marketing_pipeline!$C:$C,'Budget Summary'!M$3) -> 700 | O22: =SUMIFS($B22:$M22,$B$2:$M$2,O$3) -> 2590 | P22: =SUMIFS($B22:$M22,$B$2:$M$2,P$3) -> 1825 | Q22: =SUMIFS($B22:$M22,$B$2:$M$2,Q$3) -> 2184 | R22: =SUMIFS($B22:$M22,$B$2:$M$2,R$3) -> 3225 | T22: =SUM(O22:R22) -> 9824
A23: Webinar | B23: =SUMIFS(Budget_marketing_pipeline!$E:$E,Budget_marketing_pipeline!$D:$D,'Budget Summary'!$A23,Budget_marketing_pipeline!$C:$C,'Budget Summary'!B$3) -> 302 | C23: =SUMIFS(Budget_marketing_pipeline!$E:$E,Budget_marketing_pipeline!$D:$D,'Budget Summary'!$A23,Budget_marketing_pipeline!$C:$C,'Budget Summary'!C$3) -> 599 | D23: =SUMIFS(Budget_marketing_pipeline!$E:$E,Budget_marketing_pipeline!$D:$D,'Budget Summary'!$A23,Budget_marketing_pipeline!$C:$C,'Budget Summary'!D$3) -> 274 | E23: =SUMIFS(Budget_marketing_pipeline!$E:$E,Budget_marketing_pipeline!$D:$D,'Budget Summary'!$A23,Budget_marketing_pipeline!$C:$C,'Budget Summary'!E$3) -> 1107 | F23: =SUMIFS(Budget_marketing_pipeline!$E:$E,Budget_marketing_pipeline!$D:$D,'Budget Summary'!$A23,Budget_marketing_pipeline!$C:$C,'Budget Summary'!F$3) -> 655 | G23: =SUMIFS(Budget_marketing_pipeline!$E:$E,Budget_marketing_pipeline!$D:$D,'Budget Summary'!$A23,Budget_marketing_pipeline!$C:$C,'Budget Summary'!G$3) -> 375 | H23: =SUMIFS(Budget_marketing_pipeline!$E:$E,Budget_marketing_pipeline!$D:$D,'Budget Summary'!$A23,Budget_marketing_pipeline!$C:$C,'Budget Summary'!H$3) -> 1026 | I23: =SUMIFS(Budget_marketing_pipeline!$E:$E,Budget_marketing_pipeline!$D:$D,'Budget Summary'!$A23,Budget_marketing_pipeline!$C:$C,'Budget Summary'!I$3) -> 550 | ... M23: =SUMIFS(Budget_marketing_pipeline!$E:$E,Budget_marketing_pipeline!$D:$D,'Budget Summary'!$A23,Budget_marketing_pipeline!$C:$C,'Budget Summary'!M$3) -> 489 | O23: =SUMIFS($B23:$M23,$B$2:$M$2,O$3) -> 1175 | P23: =SUMIFS($B23:$M23,$B$2:$M$2,P$3) -> 2137 | Q23: =SUMIFS($B23:$M23,$B$2:$M$2,Q$3) -> 1944 | R23: =SUMIFS($B23:$M23,$B$2:$M$2,R$3) -> 1991 | T23: =SUM(O23:R23) -> 7247
A24: Field Event | B24: =SUMIFS(Budget_marketing_pipeline!$E:$E,Budget_marketing_pipeline!$D:$D,'Budget Summary'!$A24,Budget_marketing_pipeline!$C:$C,'Budget Summary'!B$3) -> 617 | C24: =SUMIFS(Budget_marketing_pipeline!$E:$E,Budget_marketing_pipeline!$D:$D,'Budget Summary'!$A24,Budget_marketing_pipeline!$C:$C,'Budget Summary'!C$3) -> 974 | D24: =SUMIFS(Budget_marketing_pipeline!$E:$E,Budget_marketing_pipeline!$D:$D,'Budget Summary'!$A24,Budget_marketing_pipeline!$C:$C,'Budget Summary'!D$3) -> 668 | E24: =SUMIFS(Budget_marketing_pipeline!$E:$E,Budget_marketing_pipeline!$D:$D,'Budget Summary'!$A24,Budget_marketing_pipeline!$C:$C,'Budget Summary'!E$3) -> 642 | F24: =SUMIFS(Budget_marketing_pipeline!$E:$E,Budget_marketing_pipeline!$D:$D,'Budget Summary'!$A24,Budget_marketing_pipeline!$C:$C,'Budget Summary'!F$3) -> 1281 | G24: =SUMIFS(Budget_marketing_pipeline!$E:$E,Budget_marketing_pipeline!$D:$D,'Budget Summary'!$A24,Budget_marketing_pipeline!$C:$C,'Budget Summary'!G$3) -> 566 | H24: =SUMIFS(Budget_marketing_pipeline!$E:$E,Budget_marketing_pipeline!$D:$D,'Budget Summary'!$A24,Budget_marketing_pipeline!$C:$C,'Budget Summary'!H$3) -> 691 | I24: =SUMIFS(Budget_marketing_pipeline!$E:$E,Budget_marketing_pipeline!$D:$D,'Budget Summary'!$A24,Budget_marketing_pipeline!$C:$C,'Budget Summary'!I$3) -> 945 | ... M24: =SUMIFS(Budget_marketing_pipeline!$E:$E,Budget_marketing_pipeline!$D:$D,'Budget Summary'!$A24,Budget_marketing_pipeline!$C:$C,'Budget Summary'!M$3) -> 731 | O24: =SUMIFS($B24:$M24,$B$2:$M$2,O$3) -> 2259 | P24: =SUMIFS($B24:$M24,$B$2:$M$2,P$3) -> 2489 | Q24: =SUMIFS($B24:$M24,$B$2:$M$2,Q$3) -> 2568 | R24: =SUMIFS($B24:$M24,$B$2:$M$2,R$3) -> 2194 | T24: =SUM(O24:R24) -> 9510
A25: Referral | B25: =SUMIFS(Budget_marketing_pipeline!$E:$E,Budget_marketing_pipeline!$D:$D,'Budget Summary'!$A25,Budget_marketing_pipeline!$C:$C,'Budget Summary'!B$3) -> 655 | C25: =SUMIFS(Budget_marketing_pipeline!$E:$E,Budget_marketing_pipeline!$D:$D,'Budget Summary'!$A25,Budget_marketing_pipeline!$C:$C,'Budget Summary'!C$3) -> 600 | D25: =SUMIFS(Budget_marketing_pipeline!$E:$E,Budget_marketing_pipeline!$D:$D,'Budget Summary'!$A25,Budget_marketing_pipeline!$C:$C,'Budget Summary'!D$3) -> 868 | E25: =SUMIFS(Budget_marketing_pipeline!$E:$E,Budget_marketing_pipeline!$D:$D,'Budget Summary'!$A25,Budget_marketing_pipeline!$C:$C,'Budget Summary'!E$3) -> 366 | F25: =SUMIFS(Budget_marketing_pipeline!$E:$E,Budget_marketing_pipeline!$D:$D,'Budget Summary'!$A25,Budget_marketing_pipeline!$C:$C,'Budget Summary'!F$3) -> 657 | G25: =SUMIFS(Budget_marketing_pipeline!$E:$E,Budget_marketing_pipeline!$D:$D,'Budget Summary'!$A25,Budget_marketing_pipeline!$C:$C,'Budget Summary'!G$3) -> 1380 | H25: =SUMIFS(Budget_marketing_pipeline!$E:$E,Budget_marketing_pipeline!$D:$D,'Budget Summary'!$A25,Budget_marketing_pipeline!$C:$C,'Budget Summary'!H$3) -> 1307 | I25: =SUMIFS(Budget_marketing_pipeline!$E:$E,Budget_marketing_pipeline!$D:$D,'Budget Summary'!$A25,Budget_marketing_pipeline!$C:$C,'Budget Summary'!I$3) -> 670 | ... M25: =SUMIFS(Budget_marketing_pipeline!$E:$E,Budget_marketing_pipeline!$D:$D,'Budget Summary'!$A25,Budget_marketing_pipeline!$C:$C,'Budget Summary'!M$3) -> 959 | O25: =SUMIFS($B25:$M25,$B$2:$M$2,O$3) -> 2123 | P25: =SUMIFS($B25:$M25,$B$2:$M$2,P$3) -> 2403 | Q25: =SUMIFS($B25:$M25,$B$2:$M$2,Q$3) -> 2838 | R25: =SUMIFS($B25:$M25,$B$2:$M$2,R$3) -> 2167 | T25: =SUM(O25:R25) -> 9531
A26: Direct | B26: =SUMIFS(Budget_marketing_pipeline!$E:$E,Budget_marketing_pipeline!$D:$D,'Budget Summary'!$A26,Budget_marketing_pipeline!$C:$C,'Budget Summary'!B$3) -> 302 | C26: =SUMIFS(Budget_marketing_pipeline!$E:$E,Budget_marketing_pipeline!$D:$D,'Budget Summary'!$A26,Budget_marketing_pipeline!$C:$C,'Budget Summary'!C$3) -> 695 | D26: =SUMIFS(Budget_marketing_pipeline!$E:$E,Budget_marketing_pipeline!$D:$D,'Budget Summary'!$A26,Budget_marketing_pipeline!$C:$C,'Budget Summary'!D$3) -> 745 | E26: =SUMIFS(Budget_marketing_pipeline!$E:$E,Budget_marketing_pipeline!$D:$D,'Budget Summary'!$A26,Budget_marketing_pipeline!$C:$C,'Budget Summary'!E$3) -> 511 | F26: =SUMIFS(Budget_marketing_pipeline!$E:$E,Budget_marketing_pipeline!$D:$D,'Budget Summary'!$A26,Budget_marketing_pipeline!$C:$C,'Budget Summary'!F$3) -> 1467 | G26: =SUMIFS(Budget_marketing_pipeline!$E:$E,Budget_marketing_pipeline!$D:$D,'Budget Summary'!$A26,Budget_marketing_pipeline!$C:$C,'Budget Summary'!G$3) -> 1307 | H26: =SUMIFS(Budget_marketing_pipeline!$E:$E,Budget_marketing_pipeline!$D:$D,'Budget Summary'!$A26,Budget_marketing_pipeline!$C:$C,'Budget Summary'!H$3) -> 911 | I26: =SUMIFS(Budget_marketing_pipeline!$E:$E,Budget_marketing_pipeline!$D:$D,'Budget Summary'!$A26,Budget_marketing_pipeline!$C:$C,'Budget Summary'!I$3) -> 846 | ... M26: =SUMIFS(Budget_marketing_pipeline!$E:$E,Budget_marketing_pipeline!$D:$D,'Budget Summary'!$A26,Budget_marketing_pipeline!$C:$C,'Budget Summary'!M$3) -> 1185 | O26: =SUMIFS($B26:$M26,$B$2:$M$2,O$3) -> 1742 | P26: =SUMIFS($B26:$M26,$B$2:$M$2,P$3) -> 3285 | Q26: =SUMIFS($B26:$M26,$B$2:$M$2,Q$3) -> 2254 | R26: =SUMIFS($B26:$M26,$B$2:$M$2,R$3) -> 2674 | T26: =SUM(O26:R26) -> 9955
A27: Content Syndication | B27: =SUMIFS(Budget_marketing_pipeline!$E:$E,Budget_marketing_pipeline!$D:$D,'Budget Summary'!$A27,Budget_marketing_pipeline!$C:$C,'Budget Summary'!B$3) -> 422 | C27: =SUMIFS(Budget_marketing_pipeline!$E:$E,Budget_marketing_pipeline!$D:$D,'Budget Summary'!$A27,Budget_marketing_pipeline!$C:$C,'Budget Summary'!C$3) -> 1121 | D27: =SUMIFS(Budget_marketing_pipeline!$E:$E,Budget_marketing_pipeline!$D:$D,'Budget Summary'!$A27,Budget_marketing_pipeline!$C:$C,'Budget Summary'!D$3) -> 415 | E27: =SUMIFS(Budget_marketing_pipeline!$E:$E,Budget_marketing_pipeline!$D:$D,'Budget Summary'!$A27,Budget_marketing_pipeline!$C:$C,'Budget Summary'!E$3) -> 559 | F27: =SUMIFS(Budget_marketing_pipeline!$E:$E,Budget_marketing_pipeline!$D:$D,'Budget Summary'!$A27,Budget_marketing_pipeline!$C:$C,'Budget Summary'!F$3) -> 464 | G27: =SUMIFS(Budget_marketing_pipeline!$E:$E,Budget_marketing_pipeline!$D:$D,'Budget Summary'!$A27,Budget_marketing_pipeline!$C:$C,'Budget Summary'!G$3) -> 1070 | H27: =SUMIFS(Budget_marketing_pipeline!$E:$E,Budget_marketing_pipeline!$D:$D,'Budget Summary'!$A27,Budget_marketing_pipeline!$C:$C,'Budget Summary'!H$3) -> 922 | I27: =SUMIFS(Budget_marketing_pipeline!$E:$E,Budget_marketing_pipeline!$D:$D,'Budget Summary'!$A27,Budget_marketing_pipeline!$C:$C,'Budget Summary'!I$3) -> 357 | ... M27: =SUMIFS(Budget_marketing_pipeline!$E:$E,Budget_marketing_pipeline!$D:$D,'Budget Summary'!$A27,Budget_marketing_pipeline!$C:$C,'Budget Summary'!M$3) -> 902 | O27: =SUMIFS($B27:$M27,$B$2:$M$2,O$3) -> 1958 | P27: =SUMIFS($B27:$M27,$B$2:$M$2,P$3) -> 2093 | Q27: =SUMIFS($B27:$M27,$B$2:$M$2,Q$3) -> 1700 | R27: =SUMIFS($B27:$M27,$B$2:$M$2,R$3) -> 3466 | T27: =SUM(O27:R27) -> 9217
A28: Outbound | B28: =SUMIFS(Budget_marketing_pipeline!$E:$E,Budget_marketing_pipeline!$D:$D,'Budget Summary'!$A28,Budget_marketing_pipeline!$C:$C,'Budget Summary'!B$3) -> 658 | C28: =SUMIFS(Budget_marketing_pipeline!$E:$E,Budget_marketing_pipeline!$D:$D,'Budget Summary'!$A28,Budget_marketing_pipeline!$C:$C,'Budget Summary'!C$3) -> 403 | D28: =SUMIFS(Budget_marketing_pipeline!$E:$E,Budget_marketing_pipeline!$D:$D,'Budget Summary'!$A28,Budget_marketing_pipeline!$C:$C,'Budget Summary'!D$3) -> 1408 | E28: =SUMIFS(Budget_marketing_pipeline!$E:$E,Budget_marketing_pipeline!$D:$D,'Budget Summary'!$A28,Budget_marketing_pipeline!$C:$C,'Budget Summary'!E$3) -> 702 | F28: =SUMIFS(Budget_marketing_pipeline!$E:$E,Budget_marketing_pipeline!$D:$D,'Budget Summary'!$A28,Budget_marketing_pipeline!$C:$C,'Budget Summary'!F$3) -> 517 | G28: =SUMIFS(Budget_marketing_pipeline!$E:$E,Budget_marketing_pipeline!$D:$D,'Budget Summary'!$A28,Budget_marketing_pipeline!$C:$C,'Budget Summary'!G$3) -> 1049 | H28: =SUMIFS(Budget_marketing_pipeline!$E:$E,Budget_marketing_pipeline!$D:$D,'Budget Summary'!$A28,Budget_marketing_pipeline!$C:$C,'Budget Summary'!H$3) -> 516 | I28: =SUMIFS(Budget_marketing_pipeline!$E:$E,Budget_marketing_pipeline!$D:$D,'Budget Summary'!$A28,Budget_marketing_pipeline!$C:$C,'Budget Summary'!I$3) -> 1242 | ... M28: =SUMIFS(Budget_marketing_pipeline!$E:$E,Budget_marketing_pipeline!$D:$D,'Budget Summary'!$A28,Budget_marketing_pipeline!$C:$C,'Budget Summary'!M$3) -> 421 | O28: =SUMIFS($B28:$M28,$B$2:$M$2,O$3) -> 2469 | P28: =SUMIFS($B28:$M28,$B$2:$M$2,P$3) -> 2268 | Q28: =SUMIFS($B28:$M28,$B$2:$M$2,Q$3) -> 2283 | R28: =SUMIFS($B28:$M28,$B$2:$M$2,R$3) -> 1562 | T28: =SUM(O28:R28) -> 8582
A29: Customer Success | B29: =SUMIFS(Budget_marketing_pipeline!$E:$E,Budget_marketing_pipeline!$D:$D,'Budget Summary'!$A29,Budget_marketing_pipeline!$C:$C,'Budget Summary'!B$3) -> 0 | C29: =SUMIFS(Budget_marketing_pipeline!$E:$E,Budget_marketing_pipeline!$D:$D,'Budget Summary'!$A29,Budget_marketing_pipeline!$C:$C,'Budget Summary'!C$3) -> 0 | D29: =SUMIFS(Budget_marketing_pipeline!$E:$E,Budget_marketing_pipeline!$D:$D,'Budget Summary'!$A29,Budget_marketing_pipeline!$C:$C,'Budget Summary'!D$3) -> 0 | E29: =SUMIFS(Budget_marketing_pipeline!$E:$E,Budget_marketing_pipeline!$D:$D,'Budget Summary'!$A29,Budget_marketing_pipeline!$C:$C,'Budget Summary'!E$3) -> 0 | F29: =SUMIFS(Budget_marketing_pipeline!$E:$E,Budget_marketing_pipeline!$D:$D,'Budget Summary'!$A29,Budget_marketing_pipeline!$C:$C,'Budget Summary'!F$3) -> 0 | G29: =SUMIFS(Budget_marketing_pipeline!$E:$E,Budget_marketing_pipeline!$D:$D,'Budget Summary'!$A29,Budget_marketing_pipeline!$C:$C,'Budget Summary'!G$3) -> 0 | H29: =SUMIFS(Budget_marketing_pipeline!$E:$E,Budget_marketing_pipeline!$D:$D,'Budget Summary'!$A29,Budget_marketing_pipeline!$C:$C,'Budget Summary'!H$3) -> 0 | I29: =SUMIFS(Budget_marketing_pipeline!$E:$E,Budget_marketing_pipeline!$D:$D,'Budget Summary'!$A29,Budget_marketing_pipeline!$C:$C,'Budget Summary'!I$3) -> 0 | ... M29: =SUMIFS(Budget_marketing_pipeline!$E:$E,Budget_marketing_pipeline!$D:$D,'Budget Summary'!$A29,Budget_marketing_pipeline!$C:$C,'Budget Summary'!M$3) -> 0 | O29: =SUMIFS($B29:$M29,$B$2:$M$2,O$3) -> 0 | P29: =SUMIFS($B29:$M29,$B$2:$M$2,P$3) -> 0 | Q29: =SUMIFS($B29:$M29,$B$2:$M$2,Q$3) -> 0 | R29: =SUMIFS($B29:$M29,$B$2:$M$2,R$3) -> 0 | T29: =SUM(O29:R29) -> 0
A30: Total | B30: =SUM(B19:B29) -> 6588 | C30: =SUM(C19:C29) -> 8038 | D30: =SUM(D19:D29) -> 7814 | E30: =SUM(E19:E29) -> 7599 | F30: =SUM(F19:F29) -> 7961 | G30: =SUM(G19:G29) -> 8624 | H30: =SUM(H19:H29) -> 8367 | I30: =SUM(I19:I29) -> 7136 | ... M30: =SUM(M19:M29) -> 8200 | O30: =SUMIFS($B30:$M30,$B$2:$M$2,O$3) -> 22440 | P30: =SUMIFS($B30:$M30,$B$2:$M$2,P$3) -> 24184 | Q30: =SUMIFS($B30:$M30,$B$2:$M$2,Q$3) -> 22035 | R30: =SUMIFS($B30:$M30,$B$2:$M$2,R$3) -> 25168 | T30: =SUM(O30:R30) -> 93827
A32: SQL | B32: Q1 | C32: Q1 | D32: Q1 | E32: Q2 | F32: Q2 | G32: Q2 | H32: Q3 | I32: Q3 | J32: Q3 | K32: Q4 | L32: Q4 | M32: Q4
A33: marketing_channel | B33: 2026-01 | C33: 2026-02 | D33: 2026-03 | E33: 2026-04 | F33: 2026-05 | G33: 2026-06 | H33: 2026-07 | I33: 2026-08 | J33: 2026-09 | K33: 2026-10 | L33: 2026-11 | M33: 2026-12 | O33: Q1 | P33: Q2 | Q33: Q3 | R33: Q4 | T33: FY26
A34: Paid Search | B34: =SUMIFS(Budget_marketing_pipeline!$F:$F,Budget_marketing_pipeline!$D:$D,'Budget Summary'!$A34,Budget_marketing_pipeline!$C:$C,'Budget Summary'!B$3) -> 240 | C34: =SUMIFS(Budget_marketing_pipeline!$F:$F,Budget_marketing_pipeline!$D:$D,'Budget Summary'!$A34,Budget_marketing_pipeline!$C:$C,'Budget Summary'!C$3) -> 293 | D34: =SUMIFS(Budget_marketing_pipeline!$F:$F,Budget_marketing_pipeline!$D:$D,'Budget Summary'!$A34,Budget_marketing_pipeline!$C:$C,'Budget Summary'!D$3) -> 199 | E34: =SUMIFS(Budget_marketing_pipeline!$F:$F,Budget_marketing_pipeline!$D:$D,'Budget Summary'!$A34,Budget_marketing_pipeline!$C:$C,'Budget Summary'!E$3) -> 402 | F34: =SUMIFS(Budget_marketing_pipeline!$F:$F,Budget_marketing_pipeline!$D:$D,'Budget Summary'!$A34,Budget_marketing_pipeline!$C:$C,'Budget Summary'!F$3) -> 273 | G34: =SUMIFS(Budget_marketing_pipeline!$F:$F,Budget_marketing_pipeline!$D:$D,'Budget Summary'!$A34,Budget_marketing_pipeline!$C:$C,'Budget Summary'!G$3) -> 371 | H34: =SUMIFS(Budget_marketing_pipeline!$F:$F,Budget_marketing_pipeline!$D:$D,'Budget Summary'!$A34,Budget_marketing_pipeline!$C:$C,'Budget Summary'!H$3) -> 259 | I34: =SUMIFS(Budget_marketing_pipeline!$F:$F,Budget_marketing_pipeline!$D:$D,'Budget Summary'!$A34,Budget_marketing_pipeline!$C:$C,'Budget Summary'!I$3) -> 312 | ... M34: =SUMIFS(Budget_marketing_pipeline!$F:$F,Budget_marketing_pipeline!$D:$D,'Budget Summary'!$A34,Budget_marketing_pipeline!$C:$C,'Budget Summary'!M$3) -> 389 | O34: =SUMIFS($B34:$M34,$B$2:$M$2,O$3) -> 732 | P34: =SUMIFS($B34:$M34,$B$2:$M$2,P$3) -> 1046 | Q34: =SUMIFS($B34:$M34,$B$2:$M$2,Q$3) -> 735 | R34: =SUMIFS($B34:$M34,$B$2:$M$2,R$3) -> 936 | T34: =SUM(O34:R34) -> 3449
A35: Paid Social | B35: =SUMIFS(Budget_marketing_pipeline!$F:$F,Budget_marketing_pipeline!$D:$D,'Budget Summary'!$A35,Budget_marketing_pipeline!$C:$C,'Budget Summary'!B$3) -> 266 | C35: =SUMIFS(Budget_marketing_pipeline!$F:$F,Budget_marketing_pipeline!$D:$D,'Budget Summary'!$A35,Budget_marketing_pipeline!$C:$C,'Budget Summary'!C$3) -> 122 | D35: =SUMIFS(Budget_marketing_pipeline!$F:$F,Budget_marketing_pipeline!$D:$D,'Budget Summary'!$A35,Budget_marketing_pipeline!$C:$C,'Budget Summary'!D$3) -> 419 | E35: =SUMIFS(Budget_marketing_pipeline!$F:$F,Budget_marketing_pipeline!$D:$D,'Budget Summary'!$A35,Budget_marketing_pipeline!$C:$C,'Budget Summary'!E$3) -> 384 | F35: =SUMIFS(Budget_marketing_pipeline!$F:$F,Budget_marketing_pipeline!$D:$D,'Budget Summary'!$A35,Budget_marketing_pipeline!$C:$C,'Budget Summary'!F$3) -> 251 | G35: =SUMIFS(Budget_marketing_pipeline!$F:$F,Budget_marketing_pipeline!$D:$D,'Budget Summary'!$A35,Budget_marketing_pipeline!$C:$C,'Budget Summary'!G$3) -> 123 | H35: =SUMIFS(Budget_marketing_pipeline!$F:$F,Budget_marketing_pipeline!$D:$D,'Budget Summary'!$A35,Budget_marketing_pipeline!$C:$C,'Budget Summary'!H$3) -> 276 | I35: =SUMIFS(Budget_marketing_pipeline!$F:$F,Budget_marketing_pipeline!$D:$D,'Budget Summary'!$A35,Budget_marketing_pipeline!$C:$C,'Budget Summary'!I$3) -> 174 | ... M35: =SUMIFS(Budget_marketing_pipeline!$F:$F,Budget_marketing_pipeline!$D:$D,'Budget Summary'!$A35,Budget_marketing_pipeline!$C:$C,'Budget Summary'!M$3) -> 172 | O35: =SUMIFS($B35:$M35,$B$2:$M$2,O$3) -> 807 | P35: =SUMIFS($B35:$M35,$B$2:$M$2,P$3) -> 758 | Q35: =SUMIFS($B35:$M35,$B$2:$M$2,Q$3) -> 621 | R35: =SUMIFS($B35:$M35,$B$2:$M$2,R$3) -> 763 | T35: =SUM(O35:R35) -> 2949
A36: Organic Search | B36: =SUMIFS(Budget_marketing_pipeline!$F:$F,Budget_marketing_pipeline!$D:$D,'Budget Summary'!$A36,Budget_marketing_pipeline!$C:$C,'Budget Summary'!B$3) -> 414 | C36: =SUMIFS(Budget_marketing_pipeline!$F:$F,Budget_marketing_pipeline!$D:$D,'Budget Summary'!$A36,Budget_marketing_pipeline!$C:$C,'Budget Summary'!C$3) -> 331 | D36: =SUMIFS(Budget_marketing_pipeline!$F:$F,Budget_marketing_pipeline!$D:$D,'Budget Summary'!$A36,Budget_marketing_pipeline!$C:$C,'Budget Summary'!D$3) -> 245 | E36: =SUMIFS(Budget_marketing_pipeline!$F:$F,Budget_marketing_pipeline!$D:$D,'Budget Summary'!$A36,Budget_marketing_pipeline!$C:$C,'Budget Summary'!E$3) -> 150 | F36: =SUMIFS(Budget_marketing_pipeline!$F:$F,Budget_marketing_pipeline!$D:$D,'Budget Summary'!$A36,Budget_marketing_pipeline!$C:$C,'Budget Summary'!F$3) -> 401 | G36: =SUMIFS(Budget_marketing_pipeline!$F:$F,Budget_marketing_pipeline!$D:$D,'Budget Summary'!$A36,Budget_marketing_pipeline!$C:$C,'Budget Summary'!G$3) -> 419 | H36: =SUMIFS(Budget_marketing_pipeline!$F:$F,Budget_marketing_pipeline!$D:$D,'Budget Summary'!$A36,Budget_marketing_pipeline!$C:$C,'Budget Summary'!H$3) -> 188 | I36: =SUMIFS(Budget_marketing_pipeline!$F:$F,Budget_marketing_pipeline!$D:$D,'Budget Summary'!$A36,Budget_marketing_pipeline!$C:$C,'Budget Summary'!I$3) -> 153 | ... M36: =SUMIFS(Budget_marketing_pipeline!$F:$F,Budget_marketing_pipeline!$D:$D,'Budget Summary'!$A36,Budget_marketing_pipeline!$C:$C,'Budget Summary'!M$3) -> 417 | O36: =SUMIFS($B36:$M36,$B$2:$M$2,O$3) -> 990 | P36: =SUMIFS($B36:$M36,$B$2:$M$2,P$3) -> 970 | Q36: =SUMIFS($B36:$M36,$B$2:$M$2,Q$3) -> 704 | R36: =SUMIFS($B36:$M36,$B$2:$M$2,R$3) -> 1005 | T36: =SUM(O36:R36) -> 3669
A37: Partner | B37: =SUMIFS(Budget_marketing_pipeline!$F:$F,Budget_marketing_pipeline!$D:$D,'Budget Summary'!$A37,Budget_marketing_pipeline!$C:$C,'Budget Summary'!B$3) -> 321 | C37: =SUMIFS(Budget_marketing_pipeline!$F:$F,Budget_marketing_pipeline!$D:$D,'Budget Summary'!$A37,Budget_marketing_pipeline!$C:$C,'Budget Summary'!C$3) -> 377 | D37: =SUMIFS(Budget_marketing_pipeline!$F:$F,Budget_marketing_pipeline!$D:$D,'Budget Summary'!$A37,Budget_marketing_pipeline!$C:$C,'Budget Summary'!D$3) -> 199 | E37: =SUMIFS(Budget_marketing_pipeline!$F:$F,Budget_marketing_pipeline!$D:$D,'Budget Summary'!$A37,Budget_marketing_pipeline!$C:$C,'Budget Summary'!E$3) -> 241 | F37: =SUMIFS(Budget_marketing_pipeline!$F:$F,Budget_marketing_pipeline!$D:$D,'Budget Summary'!$A37,Budget_marketing_pipeline!$C:$C,'Budget Summary'!F$3) -> 133 | G37: =SUMIFS(Budget_marketing_pipeline!$F:$F,Budget_marketing_pipeline!$D:$D,'Budget Summary'!$A37,Budget_marketing_pipeline!$C:$C,'Budget Summary'!G$3) -> 321 | H37: =SUMIFS(Budget_marketing_pipeline!$F:$F,Budget_marketing_pipeline!$D:$D,'Budget Summary'!$A37,Budget_marketing_pipeline!$C:$C,'Budget Summary'!H$3) -> 397 | I37: =SUMIFS(Budget_marketing_pipeline!$F:$F,Budget_marketing_pipeline!$D:$D,'Budget Summary'!$A37,Budget_marketing_pipeline!$C:$C,'Budget Summary'!I$3) -> 208 | ... M37: =SUMIFS(Budget_marketing_pipeline!$F:$F,Budget_marketing_pipeline!$D:$D,'Budget Summary'!$A37,Budget_marketing_pipeline!$C:$C,'Budget Summary'!M$3) -> 318 | O37: =SUMIFS($B37:$M37,$B$2:$M$2,O$3) -> 897 | P37: =SUMIFS($B37:$M37,$B$2:$M$2,P$3) -> 695 | Q37: =SUMIFS($B37:$M37,$B$2:$M$2,Q$3) -> 784 | R37: =SUMIFS($B37:$M37,$B$2:$M$2,R$3) -> 1048 | T37: =SUM(O37:R37) -> 3424
A38: Webinar | B38: =SUMIFS(Budget_marketing_pipeline!$F:$F,Budget_marketing_pipeline!$D:$D,'Budget Summary'!$A38,Budget_marketing_pipeline!$C:$C,'Budget Summary'!B$3) -> 123 | C38: =SUMIFS(Budget_marketing_pipeline!$F:$F,Budget_marketing_pipeline!$D:$D,'Budget Summary'!$A38,Budget_marketing_pipeline!$C:$C,'Budget Summary'!C$3) -> 223 | D38: =SUMIFS(Budget_marketing_pipeline!$F:$F,Budget_marketing_pipeline!$D:$D,'Budget Summary'!$A38,Budget_marketing_pipeline!$C:$C,'Budget Summary'!D$3) -> 129 | E38: =SUMIFS(Budget_marketing_pipeline!$F:$F,Budget_marketing_pipeline!$D:$D,'Budget Summary'!$A38,Budget_marketing_pipeline!$C:$C,'Budget Summary'!E$3) -> 380 | F38: =SUMIFS(Budget_marketing_pipeline!$F:$F,Budget_marketing_pipeline!$D:$D,'Budget Summary'!$A38,Budget_marketing_pipeline!$C:$C,'Budget Summary'!F$3) -> 197 | G38: =SUMIFS(Budget_marketing_pipeline!$F:$F,Budget_marketing_pipeline!$D:$D,'Budget Summary'!$A38,Budget_marketing_pipeline!$C:$C,'Budget Summary'!G$3) -> 131 | H38: =SUMIFS(Budget_marketing_pipeline!$F:$F,Budget_marketing_pipeline!$D:$D,'Budget Summary'!$A38,Budget_marketing_pipeline!$C:$C,'Budget Summary'!H$3) -> 413 | I38: =SUMIFS(Budget_marketing_pipeline!$F:$F,Budget_marketing_pipeline!$D:$D,'Budget Summary'!$A38,Budget_marketing_pipeline!$C:$C,'Budget Summary'!I$3) -> 146 | ... M38: =SUMIFS(Budget_marketing_pipeline!$F:$F,Budget_marketing_pipeline!$D:$D,'Budget Summary'!$A38,Budget_marketing_pipeline!$C:$C,'Budget Summary'!M$3) -> 163 | O38: =SUMIFS($B38:$M38,$B$2:$M$2,O$3) -> 475 | P38: =SUMIFS($B38:$M38,$B$2:$M$2,P$3) -> 708 | Q38: =SUMIFS($B38:$M38,$B$2:$M$2,Q$3) -> 679 | R38: =SUMIFS($B38:$M38,$B$2:$M$2,R$3) -> 677 | T38: =SUM(O38:R38) -> 2539
A39: Field Event | B39: =SUMIFS(Budget_marketing_pipeline!$F:$F,Budget_marketing_pipeline!$D:$D,'Budget Summary'!$A39,Budget_marketing_pipeline!$C:$C,'Budget Summary'!B$3) -> 219 | C39: =SUMIFS(Budget_marketing_pipeline!$F:$F,Budget_marketing_pipeline!$D:$D,'Budget Summary'!$A39,Budget_marketing_pipeline!$C:$C,'Budget Summary'!C$3) -> 277 | D39: =SUMIFS(Budget_marketing_pipeline!$F:$F,Budget_marketing_pipeline!$D:$D,'Budget Summary'!$A39,Budget_marketing_pipeline!$C:$C,'Budget Summary'!D$3) -> 191 | E39: =SUMIFS(Budget_marketing_pipeline!$F:$F,Budget_marketing_pipeline!$D:$D,'Budget Summary'!$A39,Budget_marketing_pipeline!$C:$C,'Budget Summary'!E$3) -> 189 | F39: =SUMIFS(Budget_marketing_pipeline!$F:$F,Budget_marketing_pipeline!$D:$D,'Budget Summary'!$A39,Budget_marketing_pipeline!$C:$C,'Budget Summary'!F$3) -> 375 | G39: =SUMIFS(Budget_marketing_pipeline!$F:$F,Budget_marketing_pipeline!$D:$D,'Budget Summary'!$A39,Budget_marketing_pipeline!$C:$C,'Budget Summary'!G$3) -> 241 | H39: =SUMIFS(Budget_marketing_pipeline!$F:$F,Budget_marketing_pipeline!$D:$D,'Budget Summary'!$A39,Budget_marketing_pipeline!$C:$C,'Budget Summary'!H$3) -> 297 | I39: =SUMIFS(Budget_marketing_pipeline!$F:$F,Budget_marketing_pipeline!$D:$D,'Budget Summary'!$A39,Budget_marketing_pipeline!$C:$C,'Budget Summary'!I$3) -> 276 | ... M39: =SUMIFS(Budget_marketing_pipeline!$F:$F,Budget_marketing_pipeline!$D:$D,'Budget Summary'!$A39,Budget_marketing_pipeline!$C:$C,'Budget Summary'!M$3) -> 250 | O39: =SUMIFS($B39:$M39,$B$2:$M$2,O$3) -> 687 | P39: =SUMIFS($B39:$M39,$B$2:$M$2,P$3) -> 805 | Q39: =SUMIFS($B39:$M39,$B$2:$M$2,Q$3) -> 882 | R39: =SUMIFS($B39:$M39,$B$2:$M$2,R$3) -> 912 | T39: =SUM(O39:R39) -> 3286
A40: Referral | B40: =SUMIFS(Budget_marketing_pipeline!$F:$F,Budget_marketing_pipeline!$D:$D,'Budget Summary'!$A40,Budget_marketing_pipeline!$C:$C,'Budget Summary'!B$3) -> 287 | C40: =SUMIFS(Budget_marketing_pipeline!$F:$F,Budget_marketing_pipeline!$D:$D,'Budget Summary'!$A40,Budget_marketing_pipeline!$C:$C,'Budget Summary'!C$3) -> 245 | D40: =SUMIFS(Budget_marketing_pipeline!$F:$F,Budget_marketing_pipeline!$D:$D,'Budget Summary'!$A40,Budget_marketing_pipeline!$C:$C,'Budget Summary'!D$3) -> 404 | E40: =SUMIFS(Budget_marketing_pipeline!$F:$F,Budget_marketing_pipeline!$D:$D,'Budget Summary'!$A40,Budget_marketing_pipeline!$C:$C,'Budget Summary'!E$3) -> 121 | F40: =SUMIFS(Budget_marketing_pipeline!$F:$F,Budget_marketing_pipeline!$D:$D,'Budget Summary'!$A40,Budget_marketing_pipeline!$C:$C,'Budget Summary'!F$3) -> 262 | G40: =SUMIFS(Budget_marketing_pipeline!$F:$F,Budget_marketing_pipeline!$D:$D,'Budget Summary'!$A40,Budget_marketing_pipeline!$C:$C,'Budget Summary'!G$3) -> 393 | H40: =SUMIFS(Budget_marketing_pipeline!$F:$F,Budget_marketing_pipeline!$D:$D,'Budget Summary'!$A40,Budget_marketing_pipeline!$C:$C,'Budget Summary'!H$3) -> 391 | I40: =SUMIFS(Budget_marketing_pipeline!$F:$F,Budget_marketing_pipeline!$D:$D,'Budget Summary'!$A40,Budget_marketing_pipeline!$C:$C,'Budget Summary'!I$3) -> 178 | ... M40: =SUMIFS(Budget_marketing_pipeline!$F:$F,Budget_marketing_pipeline!$D:$D,'Budget Summary'!$A40,Budget_marketing_pipeline!$C:$C,'Budget Summary'!M$3) -> 344 | O40: =SUMIFS($B40:$M40,$B$2:$M$2,O$3) -> 936 | P40: =SUMIFS($B40:$M40,$B$2:$M$2,P$3) -> 776 | Q40: =SUMIFS($B40:$M40,$B$2:$M$2,Q$3) -> 817 | R40: =SUMIFS($B40:$M40,$B$2:$M$2,R$3) -> 889 | T40: =SUM(O40:R40) -> 3418
A41: Direct | B41: =SUMIFS(Budget_marketing_pipeline!$F:$F,Budget_marketing_pipeline!$D:$D,'Budget Summary'!$A41,Budget_marketing_pipeline!$C:$C,'Budget Summary'!B$3) -> 133 | C41: =SUMIFS(Budget_marketing_pipeline!$F:$F,Budget_marketing_pipeline!$D:$D,'Budget Summary'!$A41,Budget_marketing_pipeline!$C:$C,'Budget Summary'!C$3) -> 328 | D41: =SUMIFS(Budget_marketing_pipeline!$F:$F,Budget_marketing_pipeline!$D:$D,'Budget Summary'!$A41,Budget_marketing_pipeline!$C:$C,'Budget Summary'!D$3) -> 290 | E41: =SUMIFS(Budget_marketing_pipeline!$F:$F,Budget_marketing_pipeline!$D:$D,'Budget Summary'!$A41,Budget_marketing_pipeline!$C:$C,'Budget Summary'!E$3) -> 233 | F41: =SUMIFS(Budget_marketing_pipeline!$F:$F,Budget_marketing_pipeline!$D:$D,'Budget Summary'!$A41,Budget_marketing_pipeline!$C:$C,'Budget Summary'!F$3) -> 391 | G41: =SUMIFS(Budget_marketing_pipeline!$F:$F,Budget_marketing_pipeline!$D:$D,'Budget Summary'!$A41,Budget_marketing_pipeline!$C:$C,'Budget Summary'!G$3) -> 386 | H41: =SUMIFS(Budget_marketing_pipeline!$F:$F,Budget_marketing_pipeline!$D:$D,'Budget Summary'!$A41,Budget_marketing_pipeline!$C:$C,'Budget Summary'!H$3) -> 264 | I41: =SUMIFS(Budget_marketing_pipeline!$F:$F,Budget_marketing_pipeline!$D:$D,'Budget Summary'!$A41,Budget_marketing_pipeline!$C:$C,'Budget Summary'!I$3) -> 294 | ... M41: =SUMIFS(Budget_marketing_pipeline!$F:$F,Budget_marketing_pipeline!$D:$D,'Budget Summary'!$A41,Budget_marketing_pipeline!$C:$C,'Budget Summary'!M$3) -> 324 | O41: =SUMIFS($B41:$M41,$B$2:$M$2,O$3) -> 751 | P41: =SUMIFS($B41:$M41,$B$2:$M$2,P$3) -> 1010 | Q41: =SUMIFS($B41:$M41,$B$2:$M$2,Q$3) -> 743 | R41: =SUMIFS($B41:$M41,$B$2:$M$2,R$3) -> 950 | T41: =SUM(O41:R41) -> 3454
A42: Content Syndication | B42: =SUMIFS(Budget_marketing_pipeline!$F:$F,Budget_marketing_pipeline!$D:$D,'Budget Summary'!$A42,Budget_marketing_pipeline!$C:$C,'Budget Summary'!B$3) -> 174 | C42: =SUMIFS(Budget_marketing_pipeline!$F:$F,Budget_marketing_pipeline!$D:$D,'Budget Summary'!$A42,Budget_marketing_pipeline!$C:$C,'Budget Summary'!C$3) -> 313 | D42: =SUMIFS(Budget_marketing_pipeline!$F:$F,Budget_marketing_pipeline!$D:$D,'Budget Summary'!$A42,Budget_marketing_pipeline!$C:$C,'Budget Summary'!D$3) -> 135 | E42: =SUMIFS(Budget_marketing_pipeline!$F:$F,Budget_marketing_pipeline!$D:$D,'Budget Summary'!$A42,Budget_marketing_pipeline!$C:$C,'Budget Summary'!E$3) -> 162 | F42: =SUMIFS(Budget_marketing_pipeline!$F:$F,Budget_marketing_pipeline!$D:$D,'Budget Summary'!$A42,Budget_marketing_pipeline!$C:$C,'Budget Summary'!F$3) -> 125 | G42: =SUMIFS(Budget_marketing_pipeline!$F:$F,Budget_marketing_pipeline!$D:$D,'Budget Summary'!$A42,Budget_marketing_pipeline!$C:$C,'Budget Summary'!G$3) -> 327 | H42: =SUMIFS(Budget_marketing_pipeline!$F:$F,Budget_marketing_pipeline!$D:$D,'Budget Summary'!$A42,Budget_marketing_pipeline!$C:$C,'Budget Summary'!H$3) -> 366 | I42: =SUMIFS(Budget_marketing_pipeline!$F:$F,Budget_marketing_pipeline!$D:$D,'Budget Summary'!$A42,Budget_marketing_pipeline!$C:$C,'Budget Summary'!I$3) -> 121 | ... M42: =SUMIFS(Budget_marketing_pipeline!$F:$F,Budget_marketing_pipeline!$D:$D,'Budget Summary'!$A42,Budget_marketing_pipeline!$C:$C,'Budget Summary'!M$3) -> 314 | O42: =SUMIFS($B42:$M42,$B$2:$M$2,O$3) -> 622 | P42: =SUMIFS($B42:$M42,$B$2:$M$2,P$3) -> 614 | Q42: =SUMIFS($B42:$M42,$B$2:$M$2,Q$3) -> 683 | R42: =SUMIFS($B42:$M42,$B$2:$M$2,R$3) -> 1081 | T42: =SUM(O42:R42) -> 3000
...

Sheet Forecast Summary
B1: Actual | C1: Actual | D1: Actual | E1: Actual | F1: Actual | G1: Forecast | H1: Forecast | I1: Forecast | J1: Forecast | K1: Forecast | L1: Forecast | M1: Forecast | O1: Actual | P1: Actual | Q1: Forecast | R1: Forecast
A2: Spending | B2: Q1 | C2: Q1 | D2: Q1 | E2: Q2 | F2: Q2 | G2: Q2 | H2: Q3 | I2: Q3 | J2: Q3 | K2: Q4 | L2: Q4 | M2: Q4
A3: marketing_channel | B3: 2026-01 | C3: 2026-02 | D3: 2026-03 | E3: 2026-04 | F3: 2026-05 | G3: 2026-06 | H3: 2026-07 | I3: 2026-08 | J3: 2026-09 | K3: 2026-10 | L3: 2026-11 | M3: 2026-12 | O3: Q1 | P3: Q2 | Q3: Q3 | R3: Q4 | T3: FY26
A4: Paid Search | B4: =SUMIFS('Trended Forecast Pipeline'!$O:$O,'Trended Forecast Pipeline'!$D:$D,'Forecast Summary'!$A4,'Trended Forecast Pipeline'!$C:$C,'Forecast Summary'!B$18) -> 311718.32 | C4: =SUMIFS('Trended Forecast Pipeline'!$O:$O,'Trended Forecast Pipeline'!$D:$D,'Forecast Summary'!$A4,'Trended Forecast Pipeline'!$C:$C,'Forecast Summary'!C$18) -> 362154.33 | D4: =SUMIFS('Trended Forecast Pipeline'!$O:$O,'Trended Forecast Pipeline'!$D:$D,'Forecast Summary'!$A4,'Trended Forecast Pipeline'!$C:$C,'Forecast Summary'!D$18) -> 516622.86 | E4: =SUMIFS('Trended Forecast Pipeline'!$O:$O,'Trended Forecast Pipeline'!$D:$D,'Forecast Summary'!$A4,'Trended Forecast Pipeline'!$C:$C,'Forecast Summary'!E$18) -> 411801.63 | F4: =SUMIFS('Trended Forecast Pipeline'!$O:$O,'Trended Forecast Pipeline'!$D:$D,'Forecast Summary'!$A4,'Trended Forecast Pipeline'!$C:$C,'Forecast Summary'!F$18) -> 538298.39 | G4: =SUMIFS('Trended Forecast Pipeline'!$O:$O,'Trended Forecast Pipeline'!$D:$D,'Forecast Summary'!$A4,'Trended Forecast Pipeline'!$C:$C,'Forecast Summary'!G$18) -> 574115.94 | H4: =SUMIFS('Trended Forecast Pipeline'!$O:$O,'Trended Forecast Pipeline'!$D:$D,'Forecast Summary'!$A4,'Trended Forecast Pipeline'!$C:$C,'Forecast Summary'!H$18) -> 484707.29 | I4: =SUMIFS('Trended Forecast Pipeline'!$O:$O,'Trended Forecast Pipeline'!$D:$D,'Forecast Summary'!$A4,'Trended Forecast Pipeline'!$C:$C,'Forecast Summary'!I$18) -> 489581.55 | ... M4: =SUMIFS('Trended Forecast Pipeline'!$O:$O,'Trended Forecast Pipeline'!$D:$D,'Forecast Summary'!$A4,'Trended Forecast Pipeline'!$C:$C,'Forecast Summary'!M$18) -> 429866.95 | O4: =SUMIFS($B4:$M4,$B$2:$M$2,O$3) -> 1190495.5 | P4: =SUMIFS($B4:$M4,$B$2:$M$2,P$3) -> 1524216 | Q4: =SUMIFS($B4:$M4,$B$2:$M$2,Q$3) -> 1414275.9 | R4: =SUMIFS($B4:$M4,$B$2:$M$2,R$3) -> 1211042.2 | T4: =SUM(O4:R4) -> 5340029.6
A5: Paid Social | B5: =SUMIFS('Trended Forecast Pipeline'!$O:$O,'Trended Forecast Pipeline'!$D:$D,'Forecast Summary'!$A5,'Trended Forecast Pipeline'!$C:$C,'Forecast Summary'!B$18) -> 253030.8 | C5: =SUMIFS('Trended Forecast Pipeline'!$O:$O,'Trended Forecast Pipeline'!$D:$D,'Forecast Summary'!$A5,'Trended Forecast Pipeline'!$C:$C,'Forecast Summary'!C$18) -> 271874.14 | D5: =SUMIFS('Trended Forecast Pipeline'!$O:$O,'Trended Forecast Pipeline'!$D:$D,'Forecast Summary'!$A5,'Trended Forecast Pipeline'!$C:$C,'Forecast Summary'!D$18) -> 409763.31 | E5: =SUMIFS('Trended Forecast Pipeline'!$O:$O,'Trended Forecast Pipeline'!$D:$D,'Forecast Summary'!$A5,'Trended Forecast Pipeline'!$C:$C,'Forecast Summary'!E$18) -> 356762.81 | F5: =SUMIFS('Trended Forecast Pipeline'!$O:$O,'Trended Forecast Pipeline'!$D:$D,'Forecast Summary'!$A5,'Trended Forecast Pipeline'!$C:$C,'Forecast Summary'!F$18) -> 410414.76 | G5: =SUMIFS('Trended Forecast Pipeline'!$O:$O,'Trended Forecast Pipeline'!$D:$D,'Forecast Summary'!$A5,'Trended Forecast Pipeline'!$C:$C,'Forecast Summary'!G$18) -> 393756.03 | H5: =SUMIFS('Trended Forecast Pipeline'!$O:$O,'Trended Forecast Pipeline'!$D:$D,'Forecast Summary'!$A5,'Trended Forecast Pipeline'!$C:$C,'Forecast Summary'!H$18) -> 318414.88 | I5: =SUMIFS('Trended Forecast Pipeline'!$O:$O,'Trended Forecast Pipeline'!$D:$D,'Forecast Summary'!$A5,'Trended Forecast Pipeline'!$C:$C,'Forecast Summary'!I$18) -> 344671.14 | ... M5: =SUMIFS('Trended Forecast Pipeline'!$O:$O,'Trended Forecast Pipeline'!$D:$D,'Forecast Summary'!$A5,'Trended Forecast Pipeline'!$C:$C,'Forecast Summary'!M$18) -> 306178.22 | O5: =SUMIFS($B5:$M5,$B$2:$M$2,O$3) -> 934668.25 | P5: =SUMIFS($B5:$M5,$B$2:$M$2,P$3) -> 1160933.6 | Q5: =SUMIFS($B5:$M5,$B$2:$M$2,Q$3) -> 952409.97 | R5: =SUMIFS($B5:$M5,$B$2:$M$2,R$3) -> 846960.56 | T5: =SUM(O5:R5) -> 3894972.4
